Workbook

Sheet Instructions
A1: StepCat Workbook Instructions — v253.2
A2: Google Sheets working version with insertion-safe expanding formulas and migration guidance.
A3: Start here | B3: Create one Google Sheets copy for everyday use. Enter or paste records in Game Records A:M beginning at row 5. N:Z calculate automatically and must not be edited.
A4: Cross-device use | B4: The Google Sheet is the permanent cross-device record and can be maintained directly without StepCat. Open the same Sheet on any device signed into the same Google account, enter or paste A:M, and leave N:Z untouched so the workbook calculates automatically. StepCat's unfinished fields, settings, and Saved History remain in the current browser/device and do not transfer automatically.
A5: Editable columns | B5: Use A:M for record information. N:Z are generated by protected expanding formulas anchored above the record area. Inserting a whole row above or below an existing record does not require copying formulas.
A6: Correcting an existing record | B6: Edit only the incorrect A:M input cells on the existing Game Records row. N:Z recalculate automatically. Do not replace, clear, or edit the calculated cells.
A7: Desktop transfer or relocation | B7: On a computer, copy only populated A:M values. Insert a whole destination row, select its column-A cell, and use Paste special -> Values only. Confirm N:Z, Record Review, and totals before deleting the original row.
A8: Mobile transfer or relocation | B8: On mobile, the easiest way to add a record between existing records is to insert a whole worksheet row above the desired position, then enter or paste A:M. The red ACTIVE RECORD BOUNDARY moves down temporarily. Afterward, delete the same number of unused blank rows immediately above the red boundary to return it to row 505. Never copy an entire row because it includes N:Z.
A9: Profit rule | B9: Enter the total payout returned by the platform in Final Payout / Chips, not profit alone. Example: a $40 entry with $3.36 profit is entered as $43.36. Profit means Result Earned is above Entry Fee.
A10: Draw rule | B10: A normal completed paid game earning the Entry Fee or less is treated as a Draw with $0.00 net profit. The exact raw estimate remains visible in Estimated Earned.
A11: Loss rule | B11: A monetary loss occurs only when Disqualified / Lost Entry Fee is Yes on a paid entry; the full Entry Fee is counted as lost.
A12: Subscriptions | B12: For the annual platform membership, select “Subscription / Membership Fee,” enter the annual cost in Entry Fee, and set Disqualified / Lost Entry Fee to No. Gross Pot, Eligible Players, Total Players, and Final Payout may be entered as N/A because this is a non-game expense. Subscription rows do not change Running Net Game Profit; Summary subtracts membership/subscription costs separately when calculating Actual Running Net Profit.
A13: Free games | B13: Select “Free Game / Chips” for a completed free-entry challenge or a record that awards chips/game credit. Enter chips in Final Payout / Chips when known. Choose No in Disqualified / Lost Entry Fee for a completed free game and Yes only if it was disqualified. Game Type may be N/A only when historical membership status is unavailable.
A14: Summary | B14: Summary uses exact counts and cash totals. Free Games are shown separately from paid-game Profit, Draw, and Disqualified counts, and their chips are reported in a separate non-cash total.
... A31: Carryover alternative | B31: Use only when starting a fresh record list without transferring prior Game Records rows. Enter prior totals once, then continue with new records.
A32: Prior Net Game Profit | B32: 0
A33: Prior Subscription Costs | B33: 0
A34: Prior Game Count | B34: 0
A35: Step 1 — Note prior totals | B35: If you are not transferring the prior A:M records, open the completed or archived workbook and note its ending Net Game Profit, subscription costs already paid, and completed-game count.
A36: Step 2 — Enter once | B36: Enter those three figures once in B32:B34. Do not also copy the prior Game Records rows; using both methods would count the same activity twice.
A37: Step 3 — Continue records | B37: Begin new records on Game Records row 5. Enter only activity that occurred after the previous workbook ended.
A38: Step 4 — Check totals | B38: Running totals and Summary should begin with the carryover figures and then add only the new workbook's records.
A39: Important | B39: Carryover is an alternative to transferring prior rows. If you copy populated A5:M records into this workbook, leave B32:B34 at 0. Prior Game Count includes completed games only; exclude Subscription rows and unfinished Estimate rows.
A41: Calculations | B41: Reference for how the workbook determines results and totals.
A42: Member games | B42: Adjusted Pot uses 100% of Gross Pot.
A43: Release date | B43: August 23, 2026
A44: What's new as of August 23, 2026 | B44: Workbook v253.2 adds automatic Estimate finalization status: blue marks games still in progress through their End Date, amber marks records ready to finalize after the End Date passes, and red flags Estimates with a missing or unusable End Date. Record Review now reports the same statuses and totals. The documented whole-row insertion / boundary-restoration workflow remains in place. Core Game Records N:Z profitability formulas and Summary calculations are unchanged.
A45: Profit | B45: Result Earned above Entry Fee; Net Profit is Result Earned minus Entry Fee.
A46: Draw | B46: A normal completed paid game earning the Entry Fee or less records $0.00 Net Profit while preserving the exact Estimated Earned or Final Payout amount.
A47: Disqualified | B47: Paid entry: Final Payout / Chips and Result Earned / Chips should show $0.00, and the full Entry Fee is recorded as lost. Free Game: the disqualification status is preserved, 0.00 chips are earned, and no monetary Entry Fee loss is recorded.
... A57: Previous release — August 22, 2026 | B57: Workbook v253.1 added shorter Free Game and Subscription labels, consistent numeric/N/A alignment, the documented mobile row-insertion workflow that restores the 500-record boundary, and expanded Best Results reporting.

Sheet Game Records
A1: ="Running Net Game Profit: "&TEXT(Instructions!$B$32+SUM($W:$W),"$#,##0.00")&" | Gross Profit Earned: "&TEXT(SUM($Q:$Q),"$#,##0.00")&" | Total Lost Entry Fees: "&TEXT(SUM($S:$S),"$#,##0.00")&" | StepCat v253.1 + Workbook v253.2" -> Running Net Game Profit: $0.00 | Gross Profit Earned: $0.00 | Total Lost Entry Fees: $0.00 | StepCat v253.1 + Workbook v253.2
A2: Google Sheets working version v253.2. Enter or paste in A:M only. N:Z are generated by protected expanding formulas anchored above the record area; do not edit or paste into N:Z.
A3: A:M — Inputs only | N3: N:Z — Protected formulas
A4: Game Name | B4: Start Date | C4: End Date | D4: Entry Mode | E4: Game Type | F4: Payment / Record Type | G4: Gross Pot / Chips | H4: Entry Fee | I4: Eligible Players | J4: Total Players | K4: Final Payout / Chips | L4: Disqualified / Lost Entry Fee | M4: Notes | N4: {=VSTACK("Adjusted Pot / Chips",MAP(INDEX(A:A,5):INDEX(A:A,ROWS(A:A)),INDEX(F:F,5):INDEX(F:F,ROWS(F:F)),INDEX(G:G,5):INDEX(G:G,ROWS(G:G)),INDEX(H:H,5):INDEX(H:H,ROWS(H:H)),INDEX(E:E,5):INDEX(E:E,ROWS(E:E)),LAMBDA(a,f,g,h,e,IF(COUNTA(a,f,g,h,e)=0,"",IF(OR(LEFT(LOWER(TRIM(f&"")),12)="subscription",LOWER(TRIM(f&""))="membership"),"",IF(OR(AND(h<>"",h=0),LEFT(LOWER(TRIM(f&"")),9)="free game",LOWER(TRIM(f&""))="free",LOWER(TRIM(f&""))="free entry"),IF(ISNUMBER(g),IF(ISNUMBER(SEARCH("non",LOWER(e&""))),g*0.85,g),"N/A"),IF(g="","",IFERROR(IF(ISNUMBER(SEARCH("non",LOWER(e&""))),g*0.85,g),""))))))))} -> Adjusted Pot / Chips | O4: {=VSTACK("Estimated Earned / Chips",MAP(INDEX(A:A,5):INDEX(A:A,ROWS(A:A)),INDEX(F:F,5):INDEX(F:F,ROWS(F:F)),INDEX(H:H,5):INDEX(H:H,ROWS(H:H)),INDEX(N:N,5):INDEX(N:N,ROWS(N:N)),INDEX(I:I,5):INDEX(I:I,ROWS(I:I)),LAMBDA(a,f,h,n,i,IF(COUNTA(a,f,h,n,i)=0,"",IF(OR(LEFT(LOWER(TRIM(f&"")),12)="subscription",LOWER(TRIM(f&""))="membership"),"",IF(OR(AND(h<>"",h=0),LEFT(LOWER(TRIM(f&"")),9)="free game",LOWER(TRIM(f&""))="free",LOWER(TRIM(f&""))="free entry"),IF(OR(NOT(ISNUMBER(n)),NOT(ISNUMBER(i)),i=0),"N/A",IFERROR(n/i,"N/A")),IF(OR(n="",i="",i=0),"",IFERROR(n/i,""))))))))} -> Estimated Earned / Chips | P4: {=VSTACK("Result Earned / Chips",MAP(INDEX(A:A,5):INDEX(A:A,ROWS(A:A)),INDEX(F:F,5):INDEX(F:F,ROWS(F:F)),INDEX(L:L,5):INDEX(L:L,ROWS(L:L)),INDEX(H:H,5):INDEX(H:H,ROWS(H:H)),INDEX(D:D,5):INDEX(D:D,ROWS(D:D)),INDEX(K:K,5):INDEX(K:K,ROWS(K:K)),INDEX(O:O,5):INDEX(O:O,ROWS(O:O)),LAMBDA(a,f,l,h,d,k,o,IF(COUNTA(a,f,l,h,d,k,o)=0,"",IF(OR(LEFT(LOWER(TRIM(f&"")),12)="subscription",LOWER(TRIM(f&""))="membership"),"",IF(LOWER(l&"")="yes",0,IF(OR(AND(h<>"",h=0),LEFT(LOWER(TRIM(f&"")),9)="free game",LOWER(TRIM(f&""))="free",LOWER(TRIM(f&""))="free entry"),IF(LOWER(d&"")="finalized",IF(ISNUMBER(k),k,""),IF(o<>"",o,"")),IF(k<>"",k,IF(o<>"",o,"")))))))))} -> Result Earned / Chips | Q4: {=VSTACK("Profit",MAP(INDEX(A:A,5):INDEX(A:A,ROWS(A:A)),INDEX(U:U,5):INDEX(U:U,ROWS(U:U)),INDEX(P:P,5):INDEX(P:P,ROWS(P:P)),INDEX(H:H,5):INDEX(H:H,ROWS(H:H)),LAMBDA(a,u,p,h,IF(COUNTA(a,u,p,h)=0,"",IF(OR(u="Subscription",u=""),"",IF(u="Estimate","N/A",IF(u="Profit",ROUND(IFERROR(p,0)-IFERROR(h,0),2),0)))))))} -> Profit | R4: {=VSTACK("Draw",MAP(INDEX(A:A,5):INDEX(A:A,ROWS(A:A)),INDEX(U:U,5):INDEX(U:U,ROWS(U:U)),INDEX(H:H,5):INDEX(H:H,ROWS(H:H)),LAMBDA(a,u,h,IF(COUNTA(a,u,h)=0,"",IF(OR(u="Subscription",u=""),"",IF(u="Estimate","N/A",IF(u="Draw",h,0)))))))} -> Draw | S4: {=VSTACK("Lost",MAP(INDEX(A:A,5):INDEX(A:A,ROWS(A:A)),INDEX(U:U,5):INDEX(U:U,ROWS(U:U)),INDEX(H:H,5):INDEX(H:H,ROWS(H:H)),LAMBDA(a,u,h,IF(COUNTA(a,u,h)=0,"",IF(OR(u="Subscription",u=""),"",IF(u="Estimate","N/A",IF(u="Disqualified",h,0)))))))} -> Lost | T4: {=VSTACK("ROI",MAP(INDEX(A:A,5):INDEX(A:A,ROWS(A:A)),INDEX(U:U,5):INDEX(U:U,ROWS(U:U)),INDEX(H:H,5):INDEX(H:H,ROWS(H:H)),INDEX(Q:Q,5):INDEX(Q:Q,ROWS(Q:Q)),INDEX(S:S,5):INDEX(S:S,ROWS(S:S)),LAMBDA(a,u,h,q,s,IF(COUNTA(a,u,h,q,s)=0,"",IF(OR(u="Subscription",u=""),"",IF(u="Estimate","N/A",IF(OR(u="Free Game",u="Disqualified — Free Game",h=0),"N/A",IF(u="Profit",q/h,IF(u="Disqualified",-s/h,0)))))))))} -> ROI | U4: {=VSTACK("Result",MAP(INDEX(A:A,5):INDEX(A:A,ROWS(A:A)),INDEX(F:F,5):INDEX(F:F,ROWS(F:F)),INDEX(H:H,5):INDEX(H:H,ROWS(H:H)),INDEX(L:L,5):INDEX(L:L,ROWS(L:L)),INDEX(P:P,5):INDEX(P:P,ROWS(P:P)),INDEX(D:D,5):INDEX(D:D,ROWS(D:D)),LAMBDA(a,f,h,l,p,d,IF(COUNTA(a,f,h,l,p,d)=0,"",IF(OR(LEFT(LOWER(TRIM(f&"")),12)="subscription",LOWER(TRIM(f&""))="membership"),"Subscription",IF(LOWER(TRIM(d&""))="estimate","Estimate",IF(OR(AND(h<>"",h=0),LEFT(LOWER(TRIM(f&"")),9)="free game",LOWER(TRIM(f&""))="free",LOWER(TRIM(f&""))="free entry"),IF(LOWER(l&"")="yes","Disqualified — Free Game","Free Game"),IF(LOWER(l&"")="yes","Disqualified",IF(p="","",IF(ROUND(IFERROR(VALUE(p),0)-IFERROR(VALUE(h),0),2)>0,"Profit","Draw"))))))))))} -> Result | V4: {=VSTACK("Challenge Length (Weeks)",MAP(INDEX(A:A,5):INDEX(A:A,ROWS(A:A)),INDEX(B:B,5):INDEX(B:B,ROWS(B:B)),INDEX(C:C,5):INDEX(C:C,ROWS(C:C)),INDEX(U:U,5):INDEX(U:U,ROWS(U:U)),LAMBDA(a,b,c,u,IF(COUNTA(a,b,c,u)=0,"",IF(OR(b="",c="",u="Subscription"),"",IFERROR(ROUNDUP((c-b)/7,0),""))))))} -> Challenge Length (Weeks) | W4: {=VSTACK("Net Profit",MAP(INDEX(A:A,5):INDEX(A:A,ROWS(A:A)),INDEX(U:U,5):INDEX(U:U,ROWS(U:U)),INDEX(Q:Q,5):INDEX(Q:Q,ROWS(Q:Q)),INDEX(S:S,5):INDEX(S:S,ROWS(S:S)),LAMBDA(a,u,q,s,IF(COUNTA(a,u,q,s)=0,"",IF(OR(u="Subscription",u=""),"",IF(u="Estimate","N/A",IF(OR(u="Free Game",u="Disqualified — Free Game"),0,ROUND(IFERROR(q,0)-IFERROR(s,0),2))))))))} -> Net Profit | X4: {=VSTACK("Eliminated Players",MAP(INDEX(A:A,5):INDEX(A:A,ROWS(A:A)),INDEX(U:U,5):INDEX(U:U,ROWS(U:U)),INDEX(J:J,5):INDEX(J:J,ROWS(J:J)),INDEX(I:I,5):INDEX(I:I,ROWS(I:I)),LAMBDA(a,u,j,i,IF(COUNTA(a,u,j,i)=0,"",IF(OR(u="Subscription",NOT(ISNUMBER(j)),NOT(ISNUMBER(i)),j=0,i=0,i>j),"",j-i)))))} -> Eliminated Players | Y4: {=VSTACK("Elimination Rate",MAP(INDEX(A:A,5):INDEX(A:A,ROWS(A:A)),INDEX(U:U,5):INDEX(U:U,ROWS(U:U)),INDEX(J:J,5):INDEX(J:J,ROWS(J:J)),INDEX(X:X,5):INDEX(X:X,ROWS(X:X)),LAMBDA(a,u,j,x,IF(COUNTA(a,u,j,x)=0,"",IF(OR(u="Subscription",NOT(ISNUMBER(j)),j=0,x=""),"",x/j)))))} -> Elimination Rate | Z4: {=VSTACK("Running Net Profit",LET(mask,MAP(INDEX(A:A,5):INDEX(A:A,ROWS(A:A)),INDEX(B:B,5):INDEX(B:B,ROWS(B:B)),INDEX(C:C,5):INDEX(C:C,ROWS(C:C)),INDEX(D:D,5):INDEX(D:D,ROWS(D:D)),INDEX(E:E,5):INDEX(E:E,ROWS(E:E)),INDEX(F:F,5):INDEX(F:F,ROWS(F:F)),INDEX(G:G,5):INDEX(G:G,ROWS(G:G)),INDEX(H:H,5):INDEX(H:H,ROWS(H:H)),INDEX(I:I,5):INDEX(I:I,ROWS(I:I)),INDEX(J:J,5):INDEX(J:J,ROWS(J:J)),INDEX(K:K,5):INDEX(K:K,ROWS(K:K)),INDEX(L:L,5):INDEX(L:L,ROWS(L:L)),INDEX(M:M,5):INDEX(M:M,ROWS(M:M)),LAMBDA(a,b,c,d,e,f,g,h,i,j,k,l,m,COUNTA(a,b,c,d,e,f,g,h,i,j,k,l,m))),running,SCAN(0,INDEX(W:W,5):INDEX(W:W,ROWS(W:W)),LAMBDA(total,value,total+IFERROR(N(value),0))),IF(mask=0,"",Instructions!$B$32+running)))} -> Running Net Profit
A5: test | B5: 32685 | C5: 32715 | D5: Estimate | E5: Member | F5: Cash | G5: 20000 | H5: 40 | I5: 700 | J5: 800 | L5: No | N5: 20000 | O5: 28.571429 | P5: 28.571429 | Q5: N/A | R5: N/A | S5: N/A | T5: N/A | U5: Estimate | V5: 5 | W5: N/A | X5: 100 | Y5: 0.125 | Z5: 0
A505: ACTIVE RECORD BOUNDARY — 500 RECORDS MAXIMUM. DO NOT ENTER RECORDS BELOW THIS LINE. | Z505: 0

Sheet Record Review
A1: Record Review — Game Index and Field Review — v253.2
A2: Lists each non-subscription game, automatic Estimate finalization status, and fields that may deserve review. N:Z use expanding formulas anchored above the record area.
A4: Game # | B4: Game Records ID | C4: Game Name | D4: Calculated Result | E4: Finalization / Review Status | F4: Blank Fields to Review | G4: Notes from Game Records
A5: =IF($H5="","",ROWS($A$5:A5)) -> 1 | B5: =IF($H5="","","G-"&TEXT($A5,"0000")) -> G-0001 | C5: {=IF($H5="","",IFERROR(INDEX('Game Records'!$A:$A,$H5),""))} -> test | D5: {=IF($H5="","",IFERROR(INDEX('Game Records'!$U:$U,$H5),""))} -> Estimate | E5: {=IF($H5="","",LET(r,$H5,mode,LOWER(INDEX('Game Records'!$D:$D,r)&""),endDate,INDEX('Game Records'!$C:$C,r),IF(mode="estimate",IF(endDate="","Estimate — End Date missing",IF(NOT(ISNUMBER(endDate)),"Estimate — Check End Date",IF(INT(endDate)>=TODAY(),"In Progress — ends "&TEXT(endDate,"mmm d, yyyy"),"Ready to Finalize"))),IF($F5="","No Highlighted Fields","Highlighted Fields Present"))))} -> Ready to Finalize | F5: {=IF($H5="","",IF(OR(NOT(_xlfn.ISFORMULA(INDEX('Game Records'!$N:$N,$H5))),NOT(_xlfn.ISFORMULA(INDEX('Game Records'!$O:$O,$H5))),NOT(_xlfn.ISFORMULA(INDEX('Game Records'!$P:$P,$H5))),NOT(_xlfn.ISFORMULA(INDEX('Game Records'!$Q:$Q,$H5))),NOT(_xlfn.ISFORMULA(INDEX('Game Records'!$R:$R,$H5))),NOT(_xlfn.ISFORMULA(INDEX('Game Records'!$S:$S,$H5))),NOT(_xlfn.ISFORMULA(INDEX('Game Records'!$T:$T,$H5))),NOT(_xlfn.ISFORMULA(INDEX('Game Records'!$U:$U,$H5))),NOT(_xlfn.ISFORMULA(INDEX('Game Records'!$V:$V,$H5))),NOT(_xlfn.ISFORMULA(INDEX('Game Records'!$W:$W,$H5))),NOT(_xlfn.ISFORMULA(INDEX('Game Records'!$X:$X,$H5))),NOT(_xlfn.ISFORMULA(INDEX('Game Records'!$Y:$Y,$H5))),NOT(_xlfn.ISFORMULA(INDEX('Game Records'!$Z:$Z,$H5)))),"","")&IF(INDEX('Game Records'!$B:$B,$H5)="","Start Date; ","")&IF(INDEX('Game Records'!$C:$C,$H5)="","End Date; ","")&IF(AND(INDEX('Game Records'!$U:$U,$H5)<>"Subscription",INDEX('Game Records'!$U:$U,$H5)<>"Free Game",INDEX('Game Records'!$U:$U,$H5)<>"Disqualified — Free Game",OR(INDEX('Game Records'!$D:$D,$H5)="",LOWER(INDEX('Game Records'!$D:$D,$H5)&"")="n/a")),"Entry Mode; ","")&IF(AND(INDEX('Game Records'!$U:$U,$H5)<>"Subscription",INDEX('Game Records'!$U:$U,$H5)<>"Free Game",INDEX('Game Records'!$U:$U,$H5)<>"Disqualified — Free Game",OR(INDEX('Game Records'!$E:$E,$H5)="",LOWER(INDEX('Game Records'!$E:$E,$H5)&"")="n/a")),"Game Type; ","")&IF(INDEX('Game Records'!$F:$F,$H5)="","Payment Type; ","")&IF(AND(INDEX('Game Records'!$U:$U,$H5)<>"Subscription",INDEX('Game Records'!$U:$U,$H5)<>"Free Game",INDEX('Game Records'!$U:$U,$H5)<>"Disqualified — Free Game",INDEX('Game Records'!$G:$G,$H5)=""),"Gross Pot; ","")&IF(AND(INDEX('Game Records'!$U:$U,$H5)<>"Free Game",INDEX('Game Records'!$U:$U,$H5)<>"Disqualified — Free Game",INDEX('Game Records'!$H:$H,$H5)=""),"Entry Fee; ","")&IF(AND(INDEX('Game Records'!$U:$U,$H5)<>"Subscription",INDEX('Game Records'!$U:$U,$H5)<>"Free Game",INDEX('Game Records'!$U:$U,$H5)<>"Disqualified — Free Game",INDEX('Game Records'!$I:$I,$H5)=""),"Eligible Players; ","")&IF(AND(INDEX('Game Records'!$U:$U,$H5)<>"Subscription",INDEX('Game Records'!$U:$U,$H5)<>"Free Game",INDEX('Game Records'!$U:$U,$H5)<>"Disqualified — Free Game",INDEX('Game Records'!$J:$J,$H5)=""),"Total Players; ","")&IF(AND(LOWER(INDEX('Game Records'!$D:$D,$H5)&"")="finalized",LOWER(INDEX('Game Records'!$L:$L,$H5)&"")<>"yes",INDEX('Game Records'!$U:$U,$H5)<>"Subscription",INDEX('Game Records'!$U:$U,$H5)<>"Free Game",INDEX('Game Records'!$U:$U,$H5)<>"Disqualified — Free Game",INDEX('Game Records'!$K:$K,$H5)=""),"Final Payout; ","")&IF(AND(LOWER(INDEX('Game Records'!$D:$D,$H5)&"")="finalized",INDEX('Game Records'!$U:$U,$H5)<>"Subscription",INDEX('Game Records'!$U:$U,$H5)<>"Free Game",INDEX('Game Records'!$U:$U,$H5)<>"Disqualified — Free Game",OR(INDEX('Game Records'!$L:$L,$H5)="",LOWER(INDEX('Game Records'!$L:$L,$H5)&"")="n/a")),"Disqualified Status; ",""))} | G5: {=IF($H5="","",IFERROR(INDEX('Game Records'!$M:$M,$H5),""))} | H5: =IFERROR(__xludf.DUMMYFUNCTION("ARRAYFORMULA(IFERROR(FILTER(ROW('Game Records'!A:A),ROW('Game Records'!A:A)>=5,MAP('Game Records'!A:A,'Game Records'!B:B,'Game Records'!C:C,'Game Records'!D:D,'Game Records'!E:E,'Game Records'!F:F,'Game Records'!G:G,'Game Records'!H:H,'Game Records'!I:I,'"&"Game Records'!J:J,'Game Records'!K:K,'Game Records'!L:L,'Game Records'!M:M,LAMBDA(a,b,c,d,e,f,g,h,i,j,k,l,m,COUNTA(a,b,c,d,e,f,g,h,i,j,k,l,m)>0)),'Game Records'!U:U<>""Subscription"",LEFT('Game Records'!A:A,16)<>""ARCHIVE BOUNDARY"",LEFT('Game Records'!A:"&"A,22)<>""ACTIVE RECORD BOUNDARY""),""""))"),5.0) -> 5 | I5: Review Totals
A6: =IF($H6="","",ROWS($A$5:A6)) | B6: =IF($H6="","","G-"&TEXT($A6,"0000")) | C6: {=IF($H6="","",IFERROR(INDEX('Game Records'!$A:$A,$H6),""))} | D6: {=IF($H6="","",IFERROR(INDEX('Game Records'!$U:$U,$H6),""))} | E6: {=IF($H6="","",LET(r,$H6,mode,LOWER(INDEX('Game Records'!$D:$D,r)&""),endDate,INDEX('Game Records'!$C:$C,r),IF(mode="estimate",IF(endDate="","Estimate — End Date missing",IF(NOT(ISNUMBER(endDate)),"Estimate — Check End Date",IF(INT(endDate)>=TODAY(),"In Progress — ends "&TEXT(endDate,"mmm d, yyyy"),"Ready to Finalize"))),IF($F6="","No Highlighted Fields","Highlighted Fields Present"))))} | F6: {=IF($H6="","",IF(OR(NOT(_xlfn.ISFORMULA(INDEX('Game Records'!$N:$N,$H6))),NOT(_xlfn.ISFORMULA(INDEX('Game Records'!$O:$O,$H6))),NOT(_xlfn.ISFORMULA(INDEX('Game Records'!$P:$P,$H6))),NOT(_xlfn.ISFORMULA(INDEX('Game Records'!$Q:$Q,$H6))),NOT(_xlfn.ISFORMULA(INDEX('Game Records'!$R:$R,$H6))),NOT(_xlfn.ISFORMULA(INDEX('Game Records'!$S:$S,$H6))),NOT(_xlfn.ISFORMULA(INDEX('Game Records'!$T:$T,$H6))),NOT(_xlfn.ISFORMULA(INDEX('Game Records'!$U:$U,$H6))),NOT(_xlfn.ISFORMULA(INDEX('Game Records'!$V:$V,$H6))),NOT(_xlfn.ISFORMULA(INDEX('Game Records'!$W:$W,$H6))),NOT(_xlfn.ISFORMULA(INDEX('Game Records'!$X:$X,$H6))),NOT(_xlfn.ISFORMULA(INDEX('Game Records'!$Y:$Y,$H6))),NOT(_xlfn.ISFORMULA(INDEX('Game Records'!$Z:$Z,$H6)))),"","")&IF(INDEX('Game Records'!$B:$B,$H6)="","Start Date; ","")&IF(INDEX('Game Records'!$C:$C,$H6)="","End Date; ","")&IF(AND(INDEX('Game Records'!$U:$U,$H6)<>"Subscription",INDEX('Game Records'!$U:$U,$H6)<>"Free Game",INDEX('Game Records'!$U:$U,$H6)<>"Disqualified — Free Game",OR(INDEX('Game Records'!$D:$D,$H6)="",LOWER(INDEX('Game Records'!$D:$D,$H6)&"")="n/a")),"Entry Mode; ","")&IF(AND(INDEX('Game Records'!$U:$U,$H6)<>"Subscription",INDEX('Game Records'!$U:$U,$H6)<>"Free Game",INDEX('Game Records'!$U:$U,$H6)<>"Disqualified — Free Game",OR(INDEX('Game Records'!$E:$E,$H6)="",LOWER(INDEX('Game Records'!$E:$E,$H6)&"")="n/a")),"Game Type; ","")&IF(INDEX('Game Records'!$F:$F,$H6)="","Payment Type; ","")&IF(AND(INDEX('Game Records'!$U:$U,$H6)<>"Subscription",INDEX('Game Records'!$U:$U,$H6)<>"Free Game",INDEX('Game Records'!$U:$U,$H6)<>"Disqualified — Free Game",INDEX('Game Records'!$G:$G,$H6)=""),"Gross Pot; ","")&IF(AND(INDEX('Game Records'!$U:$U,$H6)<>"Free Game",INDEX('Game Records'!$U:$U,$H6)<>"Disqualified — Free Game",INDEX('Game Records'!$H:$H,$H6)=""),"Entry Fee; ","")&IF(AND(INDEX('Game Records'!$U:$U,$H6)<>"Subscription",INDEX('Game Records'!$U:$U,$H6)<>"Free Game",INDEX('Game Records'!$U:$U,$H6)<>"Disqualified — Free Game",INDEX('Game Records'!$I:$I,$H6)=""),"Eligible Players; ","")&IF(AND(INDEX('Game Records'!$U:$U,$H6)<>"Subscription",INDEX('Game Records'!$U:$U,$H6)<>"Free Game",INDEX('Game Records'!$U:$U,$H6)<>"Disqualified — Free Game",INDEX('Game Records'!$J:$J,$H6)=""),"Total Players; ","")&IF(AND(LOWER(INDEX('Game Records'!$D:$D,$H6)&"")="finalized",LOWER(INDEX('Game Records'!$L:$L,$H6)&"")<>"yes",INDEX('Game Records'!$U:$U,$H6)<>"Subscription",INDEX('Game Records'!$U:$U,$H6)<>"Free Game",INDEX('Game Records'!$U:$U,$H6)<>"Disqualified — Free Game",INDEX('Game Records'!$K:$K,$H6)=""),"Final Payout; ","")&IF(AND(LOWER(INDEX('Game Records'!$D:$D,$H6)&"")="finalized",INDEX('Game Records'!$U:$U,$H6)<>"Subscription",INDEX('Game Records'!$U:$U,$H6)<>"Free Game",INDEX('Game Records'!$U:$U,$H6)<>"Disqualified — Free Game",OR(INDEX('Game Records'!$L:$L,$H6)="",LOWER(INDEX('Game Records'!$L:$L,$H6)&"")="n/a")),"Disqualified Status; ",""))} | G6: {=IF($H6="","",IFERROR(INDEX('Game Records'!$M:$M,$H6),""))} | I6: Total Games | J6: =COUNT($A$5:$A$504) -> 1
A7: =IF($H7="","",ROWS($A$5:A7)) | B7: =IF($H7="","","G-"&TEXT($A7,"0000")) | C7: {=IF($H7="","",IFERROR(INDEX('Game Records'!$A:$A,$H7),""))} | D7: {=IF($H7="","",IFERROR(INDEX('Game Records'!$U:$U,$H7),""))} | E7: {=IF($H7="","",LET(r,$H7,mode,LOWER(INDEX('Game Records'!$D:$D,r)&""),endDate,INDEX('Game Records'!$C:$C,r),IF(mode="estimate",IF(endDate="","Estimate — End Date missing",IF(NOT(ISNUMBER(endDate)),"Estimate — Check End Date",IF(INT(endDate)>=TODAY(),"In Progress — ends "&TEXT(endDate,"mmm d, yyyy"),"Ready to Finalize"))),IF($F7="","No Highlighted Fields","Highlighted Fields Present"))))} | F7: {=IF($H7="","",IF(OR(NOT(_xlfn.ISFORMULA(INDEX('Game Records'!$N:$N,$H7))),NOT(_xlfn.ISFORMULA(INDEX('Game Records'!$O:$O,$H7))),NOT(_xlfn.ISFORMULA(INDEX('Game Records'!$P:$P,$H7))),NOT(_xlfn.ISFORMULA(INDEX('Game Records'!$Q:$Q,$H7))),NOT(_xlfn.ISFORMULA(INDEX('Game Records'!$R:$R,$H7))),NOT(_xlfn.ISFORMULA(INDEX('Game Records'!$S:$S,$H7))),NOT(_xlfn.ISFORMULA(INDEX('Game Records'!$T:$T,$H7))),NOT(_xlfn.ISFORMULA(INDEX('Game Records'!$U:$U,$H7))),NOT(_xlfn.ISFORMULA(INDEX('Game Records'!$V:$V,$H7))),NOT(_xlfn.ISFORMULA(INDEX('Game Records'!$W:$W,$H7))),NOT(_xlfn.ISFORMULA(INDEX('Game Records'!$X:$X,$H7))),NOT(_xlfn.ISFORMULA(INDEX('Game Records'!$Y:$Y,$H7))),NOT(_xlfn.ISFORMULA(INDEX('Game Records'!$Z:$Z,$H7)))),"","")&IF(INDEX('Game Records'!$B:$B,$H7)="","Start Date; ","")&IF(INDEX('Game Records'!$C:$C,$H7)="","End Date; ","")&IF(AND(INDEX('Game Records'!$U:$U,$H7)<>"Subscription",INDEX('Game Records'!$U:$U,$H7)<>"Free Game",INDEX('Game Records'!$U:$U,$H7)<>"Disqualified — Free Game",OR(INDEX('Game Records'!$D:$D,$H7)="",LOWER(INDEX('Game Records'!$D:$D,$H7)&"")="n/a")),"Entry Mode; ","")&IF(AND(INDEX('Game Records'!$U:$U,$H7)<>"Subscription",INDEX('Game Records'!$U:$U,$H7)<>"Free Game",INDEX('Game Records'!$U:$U,$H7)<>"Disqualified — Free Game",OR(INDEX('Game Records'!$E:$E,$H7)="",LOWER(INDEX('Game Records'!$E:$E,$H7)&"")="n/a")),"Game Type; ","")&IF(INDEX('Game Records'!$F:$F,$H7)="","Payment Type; ","")&IF(AND(INDEX('Game Records'!$U:$U,$H7)<>"Subscription",INDEX('Game Records'!$U:$U,$H7)<>"Free Game",INDEX('Game Records'!$U:$U,$H7)<>"Disqualified — Free Game",INDEX('Game Records'!$G:$G,$H7)=""),"Gross Pot; ","")&IF(AND(INDEX('Game Records'!$U:$U,$H7)<>"Free Game",INDEX('Game Records'!$U:$U,$H7)<>"Disqualified — Free Game",INDEX('Game Records'!$H:$H,$H7)=""),"Entry Fee; ","")&IF(AND(INDEX('Game Records'!$U:$U,$H7)<>"Subscription",INDEX('Game Records'!$U:$U,$H7)<>"Free Game",INDEX('Game Records'!$U:$U,$H7)<>"Disqualified — Free Game",INDEX('Game Records'!$I:$I,$H7)=""),"Eligible Players; ","")&IF(AND(INDEX('Game Records'!$U:$U,$H7)<>"Subscription",INDEX('Game Records'!$U:$U,$H7)<>"Free Game",INDEX('Game Records'!$U:$U,$H7)<>"Disqualified — Free Game",INDEX('Game Records'!$J:$J,$H7)=""),"Total Players; ","")&IF(AND(LOWER(INDEX('Game Records'!$D:$D,$H7)&"")="finalized",LOWER(INDEX('Game Records'!$L:$L,$H7)&"")<>"yes",INDEX('Game Records'!$U:$U,$H7)<>"Subscription",INDEX('Game Records'!$U:$U,$H7)<>"Free Game",INDEX('Game Records'!$U:$U,$H7)<>"Disqualified — Free Game",INDEX('Game Records'!$K:$K,$H7)=""),"Final Payout; ","")&IF(AND(LOWER(INDEX('Game Records'!$D:$D,$H7)&"")="finalized",INDEX('Game Records'!$U:$U,$H7)<>"Subscription",INDEX('Game Records'!$U:$U,$H7)<>"Free Game",INDEX('Game Records'!$U:$U,$H7)<>"Disqualified — Free Game",OR(INDEX('Game Records'!$L:$L,$H7)="",LOWER(INDEX('Game Records'!$L:$L,$H7)&"")="n/a")),"Disqualified Status; ",""))} | G7: {=IF($H7="","",IFERROR(INDEX('Game Records'!$M:$M,$H7),""))} | I7: Profit Games | J7: =COUNTIF('Game Records'!$U:$U,"Profit") -> 0
A8: =IF($H8="","",ROWS($A$5:A8)) | B8: =IF($H8="","","G-"&TEXT($A8,"0000")) | C8: {=IF($H8="","",IFERROR(INDEX('Game Records'!$A:$A,$H8),""))} | D8: {=IF($H8="","",IFERROR(INDEX('Game Records'!$U:$U,$H8),""))} | E8: {=IF($H8="","",LET(r,$H8,mode,LOWER(INDEX('Game Records'!$D:$D,r)&""),endDate,INDEX('Game Records'!$C:$C,r),IF(mode="estimate",IF(endDate="","Estimate — End Date missing",IF(NOT(ISNUMBER(endDate)),"Estimate — Check End Date",IF(INT(endDate)>=TODAY(),"In Progress — ends "&TEXT(endDate,"mmm d, yyyy"),"Ready to Finalize"))),IF($F8="","No Highlighted Fields","Highlighted Fields Present"))))} | F8: {=IF($H8="","",IF(OR(NOT(_xlfn.ISFORMULA(INDEX('Game Records'!$N:$N,$H8))),NOT(_xlfn.ISFORMULA(INDEX('Game Records'!$O:$O,$H8))),NOT(_xlfn.ISFORMULA(INDEX('Game Records'!$P:$P,$H8))),NOT(_xlfn.ISFORMULA(INDEX('Game Records'!$Q:$Q,$H8))),NOT(_xlfn.ISFORMULA(INDEX('Game Records'!$R:$R,$H8))),NOT(_xlfn.ISFORMULA(INDEX('Game Records'!$S:$S,$H8))),NOT(_xlfn.ISFORMULA(INDEX('Game Records'!$T:$T,$H8))),NOT(_xlfn.ISFORMULA(INDEX('Game Records'!$U:$U,$H8))),NOT(_xlfn.ISFORMULA(INDEX('Game Records'!$V:$V,$H8))),NOT(_xlfn.ISFORMULA(INDEX('Game Records'!$W:$W,$H8))),NOT(_xlfn.ISFORMULA(INDEX('Game Records'!$X:$X,$H8))),NOT(_xlfn.ISFORMULA(INDEX('Game Records'!$Y:$Y,$H8))),NOT(_xlfn.ISFORMULA(INDEX('Game Records'!$Z:$Z,$H8)))),"","")&IF(INDEX('Game Records'!$B:$B,$H8)="","Start Date; ","")&IF(INDEX('Game Records'!$C:$C,$H8)="","End Date; ","")&IF(AND(INDEX('Game Records'!$U:$U,$H8)<>"Subscription",INDEX('Game Records'!$U:$U,$H8)<>"Free Game",INDEX('Game Records'!$U:$U,$H8)<>"Disqualified — Free Game",OR(INDEX('Game Records'!$D:$D,$H8)="",LOWER(INDEX('Game Records'!$D:$D,$H8)&"")="n/a")),"Entry Mode; ","")&IF(AND(INDEX('Game Records'!$U:$U,$H8)<>"Subscription",INDEX('Game Records'!$U:$U,$H8)<>"Free Game",INDEX('Game Records'!$U:$U,$H8)<>"Disqualified — Free Game",OR(INDEX('Game Records'!$E:$E,$H8)="",LOWER(INDEX('Game Records'!$E:$E,$H8)&"")="n/a")),"Game Type; ","")&IF(INDEX('Game Records'!$F:$F,$H8)="","Payment Type; ","")&IF(AND(INDEX('Game Records'!$U:$U,$H8)<>"Subscription",INDEX('Game Records'!$U:$U,$H8)<>"Free Game",INDEX('Game Records'!$U:$U,$H8)<>"Disqualified — Free Game",INDEX('Game Records'!$G:$G,$H8)=""),"Gross Pot; ","")&IF(AND(INDEX('Game Records'!$U:$U,$H8)<>"Free Game",INDEX('Game Records'!$U:$U,$H8)<>"Disqualified — Free Game",INDEX('Game Records'!$H:$H,$H8)=""),"Entry Fee; ","")&IF(AND(INDEX('Game Records'!$U:$U,$H8)<>"Subscription",INDEX('Game Records'!$U:$U,$H8)<>"Free Game",INDEX('Game Records'!$U:$U,$H8)<>"Disqualified — Free Game",INDEX('Game Records'!$I:$I,$H8)=""),"Eligible Players; ","")&IF(AND(INDEX('Game Records'!$U:$U,$H8)<>"Subscription",INDEX('Game Records'!$U:$U,$H8)<>"Free Game",INDEX('Game Records'!$U:$U,$H8)<>"Disqualified — Free Game",INDEX('Game Records'!$J:$J,$H8)=""),"Total Players; ","")&IF(AND(LOWER(INDEX('Game Records'!$D:$D,$H8)&"")="finalized",LOWER(INDEX('Game Records'!$L:$L,$H8)&"")<>"yes",INDEX('Game Records'!$U:$U,$H8)<>"Subscription",INDEX('Game Records'!$U:$U,$H8)<>"Free Game",INDEX('Game Records'!$U:$U,$H8)<>"Disqualified — Free Game",INDEX('Game Records'!$K:$K,$H8)=""),"Final Payout; ","")&IF(AND(LOWER(INDEX('Game Records'!$D:$D,$H8)&"")="finalized",INDEX('Game Records'!$U:$U,$H8)<>"Subscription",INDEX('Game Records'!$U:$U,$H8)<>"Free Game",INDEX('Game Records'!$U:$U,$H8)<>"Disqualified — Free Game",OR(INDEX('Game Records'!$L:$L,$H8)="",LOWER(INDEX('Game Records'!$L:$L,$H8)&"")="n/a")),"Disqualified Status; ",""))} | G8: {=IF($H8="","",IFERROR(INDEX('Game Records'!$M:$M,$H8),""))} | I8: Draw Games | J8: =COUNTIF('Game Records'!$U:$U,"Draw") -> 0
A9: =IF($H9="","",ROWS($A$5:A9)) | B9: =IF($H9="","","G-"&TEXT($A9,"0000")) | C9: {=IF($H9="","",IFERROR(INDEX('Game Records'!$A:$A,$H9),""))} | D9: {=IF($H9="","",IFERROR(INDEX('Game Records'!$U:$U,$H9),""))} | E9: {=IF($H9="","",LET(r,$H9,mode,LOWER(INDEX('Game Records'!$D:$D,r)&""),endDate,INDEX('Game Records'!$C:$C,r),IF(mode="estimate",IF(endDate="","Estimate — End Date missing",IF(NOT(ISNUMBER(endDate)),"Estimate — Check End Date",IF(INT(endDate)>=TODAY(),"In Progress — ends "&TEXT(endDate,"mmm d, yyyy"),"Ready to Finalize"))),IF($F9="","No Highlighted Fields","Highlighted Fields Present"))))} | F9: {=IF($H9="","",IF(OR(NOT(_xlfn.ISFORMULA(INDEX('Game Records'!$N:$N,$H9))),NOT(_xlfn.ISFORMULA(INDEX('Game Records'!$O:$O,$H9))),NOT(_xlfn.ISFORMULA(INDEX('Game Records'!$P:$P,$H9))),NOT(_xlfn.ISFORMULA(INDEX('Game Records'!$Q:$Q,$H9))),NOT(_xlfn.ISFORMULA(INDEX('Game Records'!$R:$R,$H9))),NOT(_xlfn.ISFORMULA(INDEX('Game Records'!$S:$S,$H9))),NOT(_xlfn.ISFORMULA(INDEX('Game Records'!$T:$T,$H9))),NOT(_xlfn.ISFORMULA(INDEX('Game Records'!$U:$U,$H9))),NOT(_xlfn.ISFORMULA(INDEX('Game Records'!$V:$V,$H9))),NOT(_xlfn.ISFORMULA(INDEX('Game Records'!$W:$W,$H9))),NOT(_xlfn.ISFORMULA(INDEX('Game Records'!$X:$X,$H9))),NOT(_xlfn.ISFORMULA(INDEX('Game Records'!$Y:$Y,$H9))),NOT(_xlfn.ISFORMULA(INDEX('Game Records'!$Z:$Z,$H9)))),"","")&IF(INDEX('Game Records'!$B:$B,$H9)="","Start Date; ","")&IF(INDEX('Game Records'!$C:$C,$H9)="","End Date; ","")&IF(AND(INDEX('Game Records'!$U:$U,$H9)<>"Subscription",INDEX('Game Records'!$U:$U,$H9)<>"Free Game",INDEX('Game Records'!$U:$U,$H9)<>"Disqualified — Free Game",OR(INDEX('Game Records'!$D:$D,$H9)="",LOWER(INDEX('Game Records'!$D:$D,$H9)&"")="n/a")),"Entry Mode; ","")&IF(AND(INDEX('Game Records'!$U:$U,$H9)<>"Subscription",INDEX('Game Records'!$U:$U,$H9)<>"Free Game",INDEX('Game Records'!$U:$U,$H9)<>"Disqualified — Free Game",OR(INDEX('Game Records'!$E:$E,$H9)="",LOWER(INDEX('Game Records'!$E:$E,$H9)&"")="n/a")),"Game Type; ","")&IF(INDEX('Game Records'!$F:$F,$H9)="","Payment Type; ","")&IF(AND(INDEX('Game Records'!$U:$U,$H9)<>"Subscription",INDEX('Game Records'!$U:$U,$H9)<>"Free Game",INDEX('Game Records'!$U:$U,$H9)<>"Disqualified — Free Game",INDEX('Game Records'!$G:$G,$H9)=""),"Gross Pot; ","")&IF(AND(INDEX('Game Records'!$U:$U,$H9)<>"Free Game",INDEX('Game Records'!$U:$U,$H9)<>"Disqualified — Free Game",INDEX('Game Records'!$H:$H,$H9)=""),"Entry Fee; ","")&IF(AND(INDEX('Game Records'!$U:$U,$H9)<>"Subscription",INDEX('Game Records'!$U:$U,$H9)<>"Free Game",INDEX('Game Records'!$U:$U,$H9)<>"Disqualified — Free Game",INDEX('Game Records'!$I:$I,$H9)=""),"Eligible Players; ","")&IF(AND(INDEX('Game Records'!$U:$U,$H9)<>"Subscription",INDEX('Game Records'!$U:$U,$H9)<>"Free Game",INDEX('Game Records'!$U:$U,$H9)<>"Disqualified — Free Game",INDEX('Game Records'!$J:$J,$H9)=""),"Total Players; ","")&IF(AND(LOWER(INDEX('Game Records'!$D:$D,$H9)&"")="finalized",LOWER(INDEX('Game Records'!$L:$L,$H9)&"")<>"yes",INDEX('Game Records'!$U:$U,$H9)<>"Subscription",INDEX('Game Records'!$U:$U,$H9)<>"Free Game",INDEX('Game Records'!$U:$U,$H9)<>"Disqualified — Free Game",INDEX('Game Records'!$K:$K,$H9)=""),"Final Payout; ","")&IF(AND(LOWER(INDEX('Game Records'!$D:$D,$H9)&"")="finalized",INDEX('Game Records'!$U:$U,$H9)<>"Subscription",INDEX('Game Records'!$U:$U,$H9)<>"Free Game",INDEX('Game Records'!$U:$U,$H9)<>"Disqualified — Free Game",OR(INDEX('Game Records'!$L:$L,$H9)="",LOWER(INDEX('Game Records'!$L:$L,$H9)&"")="n/a")),"Disqualified Status; ",""))} | G9: {=IF($H9="","",IFERROR(INDEX('Game Records'!$M:$M,$H9),""))} | I9: Disqualified Games | J9: =COUNTIF('Game Records'!$U:$U,"Disqualified") -> 0
A10: =IF($H10="","",ROWS($A$5:A10)) | B10: =IF($H10="","","G-"&TEXT($A10,"0000")) | C10: {=IF($H10="","",IFERROR(INDEX('Game Records'!$A:$A,$H10),""))} | D10: {=IF($H10="","",IFERROR(INDEX('Game Records'!$U:$U,$H10),""))} | E10: {=IF($H10="","",LET(r,$H10,mode,LOWER(INDEX('Game Records'!$D:$D,r)&""),endDate,INDEX('Game Records'!$C:$C,r),IF(mode="estimate",IF(endDate="","Estimate — End Date missing",IF(NOT(ISNUMBER(endDate)),"Estimate — Check End Date",IF(INT(endDate)>=TODAY(),"In Progress — ends "&TEXT(endDate,"mmm d, yyyy"),"Ready to Finalize"))),IF($F10="","No Highlighted Fields","Highlighted Fields Present"))))} | F10: {=IF($H10="","",IF(OR(NOT(_xlfn.ISFORMULA(INDEX('Game Records'!$N:$N,$H10))),NOT(_xlfn.ISFORMULA(INDEX('Game Records'!$O:$O,$H10))),NOT(_xlfn.ISFORMULA(INDEX('Game Records'!$P:$P,$H10))),NOT(_xlfn.ISFORMULA(INDEX('Game Records'!$Q:$Q,$H10))),NOT(_xlfn.ISFORMULA(INDEX('Game Records'!$R:$R,$H10))),NOT(_xlfn.ISFORMULA(INDEX('Game Records'!$S:$S,$H10))),NOT(_xlfn.ISFORMULA(INDEX('Game Records'!$T:$T,$H10))),NOT(_xlfn.ISFORMULA(INDEX('Game Records'!$U:$U,$H10))),NOT(_xlfn.ISFORMULA(INDEX('Game Records'!$V:$V,$H10))),NOT(_xlfn.ISFORMULA(INDEX('Game Records'!$W:$W,$H10))),NOT(_xlfn.ISFORMULA(INDEX('Game Records'!$X:$X,$H10))),NOT(_xlfn.ISFORMULA(INDEX('Game Records'!$Y:$Y,$H10))),NOT(_xlfn.ISFORMULA(INDEX('Game Records'!$Z:$Z,$H10)))),"","")&IF(INDEX('Game Records'!$B:$B,$H10)="","Start Date; ","")&IF(INDEX('Game Records'!$C:$C,$H10)="","End Date; ","")&IF(AND(INDEX('Game Records'!$U:$U,$H10)<>"Subscription",INDEX('Game Records'!$U:$U,$H10)<>"Free Game",INDEX('Game Records'!$U:$U,$H10)<>"Disqualified — Free Game",OR(INDEX('Game Records'!$D:$D,$H10)="",LOWER(INDEX('Game Records'!$D:$D,$H10)&"")="n/a")),"Entry Mode; ","")&IF(AND(INDEX('Game Records'!$U:$U,$H10)<>"Subscription",INDEX('Game Records'!$U:$U,$H10)<>"Free Game",INDEX('Game Records'!$U:$U,$H10)<>"Disqualified — Free Game",OR(INDEX('Game Records'!$E:$E,$H10)="",LOWER(INDEX('Game Records'!$E:$E,$H10)&"")="n/a")),"Game Type; ","")&IF(INDEX('Game Records'!$F:$F,$H10)="","Payment Type; ","")&IF(AND(INDEX('Game Records'!$U:$U,$H10)<>"Subscription",INDEX('Game Records'!$U:$U,$H10)<>"Free Game",INDEX('Game Records'!$U:$U,$H10)<>"Disqualified — Free Game",INDEX('Game Records'!$G:$G,$H10)=""),"Gross Pot; ","")&IF(AND(INDEX('Game Records'!$U:$U,$H10)<>"Free Game",INDEX('Game Records'!$U:$U,$H10)<>"Disqualified — Free Game",INDEX('Game Records'!$H:$H,$H10)=""),"Entry Fee; ","")&IF(AND(INDEX('Game Records'!$U:$U,$H10)<>"Subscription",INDEX('Game Records'!$U:$U,$H10)<>"Free Game",INDEX('Game Records'!$U:$U,$H10)<>"Disqualified — Free Game",INDEX('Game Records'!$I:$I,$H10)=""),"Eligible Players; ","")&IF(AND(INDEX('Game Records'!$U:$U,$H10)<>"Subscription",INDEX('Game Records'!$U:$U,$H10)<>"Free Game",INDEX('Game Records'!$U:$U,$H10)<>"Disqualified — Free Game",INDEX('Game Records'!$J:$J,$H10)=""),"Total Players; ","")&IF(AND(LOWER(INDEX('Game Records'!$D:$D,$H10)&"")="finalized",LOWER(INDEX('Game Records'!$L:$L,$H10)&"")<>"yes",INDEX('Game Records'!$U:$U,$H10)<>"Subscription",INDEX('Game Records'!$U:$U,$H10)<>"Free Game",INDEX('Game Records'!$U:$U,$H10)<>"Disqualified — Free Game",INDEX('Game Records'!$K:$K,$H10)=""),"Final Payout; ","")&IF(AND(LOWER(INDEX('Game Records'!$D:$D,$H10)&"")="finalized",INDEX('Game Records'!$U:$U,$H10)<>"Subscription",INDEX('Game Records'!$U:$U,$H10)<>"Free Game",INDEX('Game Records'!$U:$U,$H10)<>"Disqualified — Free Game",OR(INDEX('Game Records'!$L:$L,$H10)="",LOWER(INDEX('Game Records'!$L:$L,$H10)&"")="n/a")),"Disqualified Status; ",""))} | G10: {=IF($H10="","",IFERROR(INDEX('Game Records'!$M:$M,$H10),""))} | I10: Free Games | J10: =COUNTIF('Game Records'!$U:$U,"Free Game")+COUNTIF('Game Records'!$U:$U,"Disqualified — Free Game") -> 0
A11: =IF($H11="","",ROWS($A$5:A11)) | B11: =IF($H11="","","G-"&TEXT($A11,"0000")) | C11: {=IF($H11="","",IFERROR(INDEX('Game Records'!$A:$A,$H11),""))} | D11: {=IF($H11="","",IFERROR(INDEX('Game Records'!$U:$U,$H11),""))} | E11: {=IF($H11="","",LET(r,$H11,mode,LOWER(INDEX('Game Records'!$D:$D,r)&""),endDate,INDEX('Game Records'!$C:$C,r),IF(mode="estimate",IF(endDate="","Estimate — End Date missing",IF(NOT(ISNUMBER(endDate)),"Estimate — Check End Date",IF(INT(endDate)>=TODAY(),"In Progress — ends "&TEXT(endDate,"mmm d, yyyy"),"Ready to Finalize"))),IF($F11="","No Highlighted Fields","Highlighted Fields Present"))))} | F11: {=IF($H11="","",IF(OR(NOT(_xlfn.ISFORMULA(INDEX('Game Records'!$N:$N,$H11))),NOT(_xlfn.ISFORMULA(INDEX('Game Records'!$O:$O,$H11))),NOT(_xlfn.ISFORMULA(INDEX('Game Records'!$P:$P,$H11))),NOT(_xlfn.ISFORMULA(INDEX('Game Records'!$Q:$Q,$H11))),NOT(_xlfn.ISFORMULA(INDEX('Game Records'!$R:$R,$H11))),NOT(_xlfn.ISFORMULA(INDEX('Game Records'!$S:$S,$H11))),NOT(_xlfn.ISFORMULA(INDEX('Game Records'!$T:$T,$H11))),NOT(_xlfn.ISFORMULA(INDEX('Game Records'!$U:$U,$H11))),NOT(_xlfn.ISFORMULA(INDEX('Game Records'!$V:$V,$H11))),NOT(_xlfn.ISFORMULA(INDEX('Game Records'!$W:$W,$H11))),NOT(_xlfn.ISFORMULA(INDEX('Game Records'!$X:$X,$H11))),NOT(_xlfn.ISFORMULA(INDEX('Game Records'!$Y:$Y,$H11))),NOT(_xlfn.ISFORMULA(INDEX('Game Records'!$Z:$Z,$H11)))),"","")&IF(INDEX('Game Records'!$B:$B,$H11)="","Start Date; ","")&IF(INDEX('Game Records'!$C:$C,$H11)="","End Date; ","")&IF(AND(INDEX('Game Records'!$U:$U,$H11)<>"Subscription",INDEX('Game Records'!$U:$U,$H11)<>"Free Game",INDEX('Game Records'!$U:$U,$H11)<>"Disqualified — Free Game",OR(INDEX('Game Records'!$D:$D,$H11)="",LOWER(INDEX('Game Records'!$D:$D,$H11)&"")="n/a")),"Entry Mode; ","")&IF(AND(INDEX('Game Records'!$U:$U,$H11)<>"Subscription",INDEX('Game Records'!$U:$U,$H11)<>"Free Game",INDEX('Game Records'!$U:$U,$H11)<>"Disqualified — Free Game",OR(INDEX('Game Records'!$E:$E,$H11)="",LOWER(INDEX('Game Records'!$E:$E,$H11)&"")="n/a")),"Game Type; ","")&IF(INDEX('Game Records'!$F:$F,$H11)="","Payment Type; ","")&IF(AND(INDEX('Game Records'!$U:$U,$H11)<>"Subscription",INDEX('Game Records'!$U:$U,$H11)<>"Free Game",INDEX('Game Records'!$U:$U,$H11)<>"Disqualified — Free Game",INDEX('Game Records'!$G:$G,$H11)=""),"Gross Pot; ","")&IF(AND(INDEX('Game Records'!$U:$U,$H11)<>"Free Game",INDEX('Game Records'!$U:$U,$H11)<>"Disqualified — Free Game",INDEX('Game Records'!$H:$H,$H11)=""),"Entry Fee; ","")&IF(AND(INDEX('Game Records'!$U:$U,$H11)<>"Subscription",INDEX('Game Records'!$U:$U,$H11)<>"Free Game",INDEX('Game Records'!$U:$U,$H11)<>"Disqualified — Free Game",INDEX('Game Records'!$I:$I,$H11)=""),"Eligible Players; ","")&IF(AND(INDEX('Game Records'!$U:$U,$H11)<>"Subscription",INDEX('Game Records'!$U:$U,$H11)<>"Free Game",INDEX('Game Records'!$U:$U,$H11)<>"Disqualified — Free Game",INDEX('Game Records'!$J:$J,$H11)=""),"Total Players; ","")&IF(AND(LOWER(INDEX('Game Records'!$D:$D,$H11)&"")="finalized",LOWER(INDEX('Game Records'!$L:$L,$H11)&"")<>"yes",INDEX('Game Records'!$U:$U,$H11)<>"Subscription",INDEX('Game Records'!$U:$U,$H11)<>"Free Game",INDEX('Game Records'!$U:$U,$H11)<>"Disqualified — Free Game",INDEX('Game Records'!$K:$K,$H11)=""),"Final Payout; ","")&IF(AND(LOWER(INDEX('Game Records'!$D:$D,$H11)&"")="finalized",INDEX('Game Records'!$U:$U,$H11)<>"Subscription",INDEX('Game Records'!$U:$U,$H11)<>"Free Game",INDEX('Game Records'!$U:$U,$H11)<>"Disqualified — Free Game",OR(INDEX('Game Records'!$L:$L,$H11)="",LOWER(INDEX('Game Records'!$L:$L,$H11)&"")="n/a")),"Disqualified Status; ",""))} | G11: {=IF($H11="","",IFERROR(INDEX('Game Records'!$M:$M,$H11),""))} | I11: Points Games | J11: =COUNTIF('Game Records'!$F:$F,"Points") -> 0
A12: =IF($H12="","",ROWS($A$5:A12)) | B12: =IF($H12="","","G-"&TEXT($A12,"0000")) | C12: {=IF($H12="","",IFERROR(INDEX('Game Records'!$A:$A,$H12),""))} | D12: {=IF($H12="","",IFERROR(INDEX('Game Records'!$U:$U,$H12),""))} | E12: {=IF($H12="","",LET(r,$H12,mode,LOWER(INDEX('Game Records'!$D:$D,r)&""),endDate,INDEX('Game Records'!$C:$C,r),IF(mode="estimate",IF(endDate="","Estimate — End Date missing",IF(NOT(ISNUMBER(endDate)),"Estimate — Check End Date",IF(INT(endDate)>=TODAY(),"In Progress — ends "&TEXT(endDate,"mmm d, yyyy"),"Ready to Finalize"))),IF($F12="","No Highlighted Fields","Highlighted Fields Present"))))} | F12: {=IF($H12="","",IF(OR(NOT(_xlfn.ISFORMULA(INDEX('Game Records'!$N:$N,$H12))),NOT(_xlfn.ISFORMULA(INDEX('Game Records'!$O:$O,$H12))),NOT(_xlfn.ISFORMULA(INDEX('Game Records'!$P:$P,$H12))),NOT(_xlfn.ISFORMULA(INDEX('Game Records'!$Q:$Q,$H12))),NOT(_xlfn.ISFORMULA(INDEX('Game Records'!$R:$R,$H12))),NOT(_xlfn.ISFORMULA(INDEX('Game Records'!$S:$S,$H12))),NOT(_xlfn.ISFORMULA(INDEX('Game Records'!$T:$T,$H12))),NOT(_xlfn.ISFORMULA(INDEX('Game Records'!$U:$U,$H12))),NOT(_xlfn.ISFORMULA(INDEX('Game Records'!$V:$V,$H12))),NOT(_xlfn.ISFORMULA(INDEX('Game Records'!$W:$W,$H12))),NOT(_xlfn.ISFORMULA(INDEX('Game Records'!$X:$X,$H12))),NOT(_xlfn.ISFORMULA(INDEX('Game Records'!$Y:$Y,$H12))),NOT(_xlfn.ISFORMULA(INDEX('Game Records'!$Z:$Z,$H12)))),"","")&IF(INDEX('Game Records'!$B:$B,$H12)="","Start Date; ","")&IF(INDEX('Game Records'!$C:$C,$H12)="","End Date; ","")&IF(AND(INDEX('Game Records'!$U:$U,$H12)<>"Subscription",INDEX('Game Records'!$U:$U,$H12)<>"Free Game",INDEX('Game Records'!$U:$U,$H12)<>"Disqualified — Free Game",OR(INDEX('Game Records'!$D:$D,$H12)="",LOWER(INDEX('Game Records'!$D:$D,$H12)&"")="n/a")),"Entry Mode; ","")&IF(AND(INDEX('Game Records'!$U:$U,$H12)<>"Subscription",INDEX('Game Records'!$U:$U,$H12)<>"Free Game",INDEX('Game Records'!$U:$U,$H12)<>"Disqualified — Free Game",OR(INDEX('Game Records'!$E:$E,$H12)="",LOWER(INDEX('Game Records'!$E:$E,$H12)&"")="n/a")),"Game Type; ","")&IF(INDEX('Game Records'!$F:$F,$H12)="","Payment Type; ","")&IF(AND(INDEX('Game Records'!$U:$U,$H12)<>"Subscription",INDEX('Game Records'!$U:$U,$H12)<>"Free Game",INDEX('Game Records'!$U:$U,$H12)<>"Disqualified — Free Game",INDEX('Game Records'!$G:$G,$H12)=""),"Gross Pot; ","")&IF(AND(INDEX('Game Records'!$U:$U,$H12)<>"Free Game",INDEX('Game Records'!$U:$U,$H12)<>"Disqualified — Free Game",INDEX('Game Records'!$H:$H,$H12)=""),"Entry Fee; ","")&IF(AND(INDEX('Game Records'!$U:$U,$H12)<>"Subscription",INDEX('Game Records'!$U:$U,$H12)<>"Free Game",INDEX('Game Records'!$U:$U,$H12)<>"Disqualified — Free Game",INDEX('Game Records'!$I:$I,$H12)=""),"Eligible Players; ","")&IF(AND(INDEX('Game Records'!$U:$U,$H12)<>"Subscription",INDEX('Game Records'!$U:$U,$H12)<>"Free Game",INDEX('Game Records'!$U:$U,$H12)<>"Disqualified — Free Game",INDEX('Game Records'!$J:$J,$H12)=""),"Total Players; ","")&IF(AND(LOWER(INDEX('Game Records'!$D:$D,$H12)&"")="finalized",LOWER(INDEX('Game Records'!$L:$L,$H12)&"")<>"yes",INDEX('Game Records'!$U:$U,$H12)<>"Subscription",INDEX('Game Records'!$U:$U,$H12)<>"Free Game",INDEX('Game Records'!$U:$U,$H12)<>"Disqualified — Free Game",INDEX('Game Records'!$K:$K,$H12)=""),"Final Payout; ","")&IF(AND(LOWER(INDEX('Game Records'!$D:$D,$H12)&"")="finalized",INDEX('Game Records'!$U:$U,$H12)<>"Subscription",INDEX('Game Records'!$U:$U,$H12)<>"Free Game",INDEX('Game Records'!$U:$U,$H12)<>"Disqualified — Free Game",OR(INDEX('Game Records'!$L:$L,$H12)="",LOWER(INDEX('Game Records'!$L:$L,$H12)&"")="n/a")),"Disqualified Status; ",""))} | G12: {=IF($H12="","",IFERROR(INDEX('Game Records'!$M:$M,$H12),""))} | I12: Cash / Hybrid Games | J12: =COUNTIF('Game Records'!$F:$F,"Cash")+COUNTIF('Game Records'!$F:$F,"Hybrid") -> 1
A13: =IF($H13="","",ROWS($A$5:A13)) | B13: =IF($H13="","","G-"&TEXT($A13,"0000")) | C13: {=IF($H13="","",IFERROR(INDEX('Game Records'!$A:$A,$H13),""))} | D13: {=IF($H13="","",IFERROR(INDEX('Game Records'!$U:$U,$H13),""))} | E13: {=IF($H13="","",LET(r,$H13,mode,LOWER(INDEX('Game Records'!$D:$D,r)&""),endDate,INDEX('Game Records'!$C:$C,r),IF(mode="estimate",IF(endDate="","Estimate — End Date missing",IF(NOT(ISNUMBER(endDate)),"Estimate — Check End Date",IF(INT(endDate)>=TODAY(),"In Progress — ends "&TEXT(endDate,"mmm d, yyyy"),"Ready to Finalize"))),IF($F13="","No Highlighted Fields","Highlighted Fields Present"))))} | F13: {=IF($H13="","",IF(OR(NOT(_xlfn.ISFORMULA(INDEX('Game Records'!$N:$N,$H13))),NOT(_xlfn.ISFORMULA(INDEX('Game Records'!$O:$O,$H13))),NOT(_xlfn.ISFORMULA(INDEX('Game Records'!$P:$P,$H13))),NOT(_xlfn.ISFORMULA(INDEX('Game Records'!$Q:$Q,$H13))),NOT(_xlfn.ISFORMULA(INDEX('Game Records'!$R:$R,$H13))),NOT(_xlfn.ISFORMULA(INDEX('Game Records'!$S:$S,$H13))),NOT(_xlfn.ISFORMULA(INDEX('Game Records'!$T:$T,$H13))),NOT(_xlfn.ISFORMULA(INDEX('Game Records'!$U:$U,$H13))),NOT(_xlfn.ISFORMULA(INDEX('Game Records'!$V:$V,$H13))),NOT(_xlfn.ISFORMULA(INDEX('Game Records'!$W:$W,$H13))),NOT(_xlfn.ISFORMULA(INDEX('Game Records'!$X:$X,$H13))),NOT(_xlfn.ISFORMULA(INDEX('Game Records'!$Y:$Y,$H13))),NOT(_xlfn.ISFORMULA(INDEX('Game Records'!$Z:$Z,$H13)))),"","")&IF(INDEX('Game Records'!$B:$B,$H13)="","Start Date; ","")&IF(INDEX('Game Records'!$C:$C,$H13)="","End Date; ","")&IF(AND(INDEX('Game Records'!$U:$U,$H13)<>"Subscription",INDEX('Game Records'!$U:$U,$H13)<>"Free Game",INDEX('Game Records'!$U:$U,$H13)<>"Disqualified — Free Game",OR(INDEX('Game Records'!$D:$D,$H13)="",LOWER(INDEX('Game Records'!$D:$D,$H13)&"")="n/a")),"Entry Mode; ","")&IF(AND(INDEX('Game Records'!$U:$U,$H13)<>"Subscription",INDEX('Game Records'!$U:$U,$H13)<>"Free Game",INDEX('Game Records'!$U:$U,$H13)<>"Disqualified — Free Game",OR(INDEX('Game Records'!$E:$E,$H13)="",LOWER(INDEX('Game Records'!$E:$E,$H13)&"")="n/a")),"Game Type; ","")&IF(INDEX('Game Records'!$F:$F,$H13)="","Payment Type; ","")&IF(AND(INDEX('Game Records'!$U:$U,$H13)<>"Subscription",INDEX('Game Records'!$U:$U,$H13)<>"Free Game",INDEX('Game Records'!$U:$U,$H13)<>"Disqualified — Free Game",INDEX('Game Records'!$G:$G,$H13)=""),"Gross Pot; ","")&IF(AND(INDEX('Game Records'!$U:$U,$H13)<>"Free Game",INDEX('Game Records'!$U:$U,$H13)<>"Disqualified — Free Game",INDEX('Game Records'!$H:$H,$H13)=""),"Entry Fee; ","")&IF(AND(INDEX('Game Records'!$U:$U,$H13)<>"Subscription",INDEX('Game Records'!$U:$U,$H13)<>"Free Game",INDEX('Game Records'!$U:$U,$H13)<>"Disqualified — Free Game",INDEX('Game Records'!$I:$I,$H13)=""),"Eligible Players; ","")&IF(AND(INDEX('Game Records'!$U:$U,$H13)<>"Subscription",INDEX('Game Records'!$U:$U,$H13)<>"Free Game",INDEX('Game Records'!$U:$U,$H13)<>"Disqualified — Free Game",INDEX('Game Records'!$J:$J,$H13)=""),"Total Players; ","")&IF(AND(LOWER(INDEX('Game Records'!$D:$D,$H13)&"")="finalized",LOWER(INDEX('Game Records'!$L:$L,$H13)&"")<>"yes",INDEX('Game Records'!$U:$U,$H13)<>"Subscription",INDEX('Game Records'!$U:$U,$H13)<>"Free Game",INDEX('Game Records'!$U:$U,$H13)<>"Disqualified — Free Game",INDEX('Game Records'!$K:$K,$H13)=""),"Final Payout; ","")&IF(AND(LOWER(INDEX('Game Records'!$D:$D,$H13)&"")="finalized",INDEX('Game Records'!$U:$U,$H13)<>"Subscription",INDEX('Game Records'!$U:$U,$H13)<>"Free Game",INDEX('Game Records'!$U:$U,$H13)<>"Disqualified — Free Game",OR(INDEX('Game Records'!$L:$L,$H13)="",LOWER(INDEX('Game Records'!$L:$L,$H13)&"")="n/a")),"Disqualified Status; ",""))} | G13: {=IF($H13="","",IFERROR(INDEX('Game Records'!$M:$M,$H13),""))} | I13: In Progress | J13: =COUNTIF($E$5:$E$504,"In Progress*") -> 0
A14: =IF($H14="","",ROWS($A$5:A14)) | B14: =IF($H14="","","G-"&TEXT($A14,"0000")) | C14: {=IF($H14="","",IFERROR(INDEX('Game Records'!$A:$A,$H14),""))} | D14: {=IF($H14="","",IFERROR(INDEX('Game Records'!$U:$U,$H14),""))} | E14: {=IF($H14="","",LET(r,$H14,mode,LOWER(INDEX('Game Records'!$D:$D,r)&""),endDate,INDEX('Game Records'!$C:$C,r),IF(mode="estimate",IF(endDate="","Estimate — End Date missing",IF(NOT(ISNUMBER(endDate)),"Estimate — Check End Date",IF(INT(endDate)>=TODAY(),"In Progress — ends "&TEXT(endDate,"mmm d, yyyy"),"Ready to Finalize"))),IF($F14="","No Highlighted Fields","Highlighted Fields Present"))))} | F14: {=IF($H14="","",IF(OR(NOT(_xlfn.ISFORMULA(INDEX('Game Records'!$N:$N,$H14))),NOT(_xlfn.ISFORMULA(INDEX('Game Records'!$O:$O,$H14))),NOT(_xlfn.ISFORMULA(INDEX('Game Records'!$P:$P,$H14))),NOT(_xlfn.ISFORMULA(INDEX('Game Records'!$Q:$Q,$H14))),NOT(_xlfn.ISFORMULA(INDEX('Game Records'!$R:$R,$H14))),NOT(_xlfn.ISFORMULA(INDEX('Game Records'!$S:$S,$H14))),NOT(_xlfn.ISFORMULA(INDEX('Game Records'!$T:$T,$H14))),NOT(_xlfn.ISFORMULA(INDEX('Game Records'!$U:$U,$H14))),NOT(_xlfn.ISFORMULA(INDEX('Game Records'!$V:$V,$H14))),NOT(_xlfn.ISFORMULA(INDEX('Game Records'!$W:$W,$H14))),NOT(_xlfn.ISFORMULA(INDEX('Game Records'!$X:$X,$H14))),NOT(_xlfn.ISFORMULA(INDEX('Game Records'!$Y:$Y,$H14))),NOT(_xlfn.ISFORMULA(INDEX('Game Records'!$Z:$Z,$H14)))),"","")&IF(INDEX('Game Records'!$B:$B,$H14)="","Start Date; ","")&IF(INDEX('Game Records'!$C:$C,$H14)="","End Date; ","")&IF(AND(INDEX('Game Records'!$U:$U,$H14)<>"Subscription",INDEX('Game Records'!$U:$U,$H14)<>"Free Game",INDEX('Game Records'!$U:$U,$H14)<>"Disqualified — Free Game",OR(INDEX('Game Records'!$D:$D,$H14)="",LOWER(INDEX('Game Records'!$D:$D,$H14)&"")="n/a")),"Entry Mode; ","")&IF(AND(INDEX('Game Records'!$U:$U,$H14)<>"Subscription",INDEX('Game Records'!$U:$U,$H14)<>"Free Game",INDEX('Game Records'!$U:$U,$H14)<>"Disqualified — Free Game",OR(INDEX('Game Records'!$E:$E,$H14)="",LOWER(INDEX('Game Records'!$E:$E,$H14)&"")="n/a")),"Game Type; ","")&IF(INDEX('Game Records'!$F:$F,$H14)="","Payment Type; ","")&IF(AND(INDEX('Game Records'!$U:$U,$H14)<>"Subscription",INDEX('Game Records'!$U:$U,$H14)<>"Free Game",INDEX('Game Records'!$U:$U,$H14)<>"Disqualified — Free Game",INDEX('Game Records'!$G:$G,$H14)=""),"Gross Pot; ","")&IF(AND(INDEX('Game Records'!$U:$U,$H14)<>"Free Game",INDEX('Game Records'!$U:$U,$H14)<>"Disqualified — Free Game",INDEX('Game Records'!$H:$H,$H14)=""),"Entry Fee; ","")&IF(AND(INDEX('Game Records'!$U:$U,$H14)<>"Subscription",INDEX('Game Records'!$U:$U,$H14)<>"Free Game",INDEX('Game Records'!$U:$U,$H14)<>"Disqualified — Free Game",INDEX('Game Records'!$I:$I,$H14)=""),"Eligible Players; ","")&IF(AND(INDEX('Game Records'!$U:$U,$H14)<>"Subscription",INDEX('Game Records'!$U:$U,$H14)<>"Free Game",INDEX('Game Records'!$U:$U,$H14)<>"Disqualified — Free Game",INDEX('Game Records'!$J:$J,$H14)=""),"Total Players; ","")&IF(AND(LOWER(INDEX('Game Records'!$D:$D,$H14)&"")="finalized",LOWER(INDEX('Game Records'!$L:$L,$H14)&"")<>"yes",INDEX('Game Records'!$U:$U,$H14)<>"Subscription",INDEX('Game Records'!$U:$U,$H14)<>"Free Game",INDEX('Game Records'!$U:$U,$H14)<>"Disqualified — Free Game",INDEX('Game Records'!$K:$K,$H14)=""),"Final Payout; ","")&IF(AND(LOWER(INDEX('Game Records'!$D:$D,$H14)&"")="finalized",INDEX('Game Records'!$U:$U,$H14)<>"Subscription",INDEX('Game Records'!$U:$U,$H14)<>"Free Game",INDEX('Game Records'!$U:$U,$H14)<>"Disqualified — Free Game",OR(INDEX('Game Records'!$L:$L,$H14)="",LOWER(INDEX('Game Records'!$L:$L,$H14)&"")="n/a")),"Disqualified Status; ",""))} | G14: {=IF($H14="","",IFERROR(INDEX('Game Records'!$M:$M,$H14),""))} | I14: Ready to Finalize | J14: =COUNTIF($E$5:$E$504,"Ready to Finalize") -> 1
A15: =IF($H15="","",ROWS($A$5:A15)) | B15: =IF($H15="","","G-"&TEXT($A15,"0000")) | C15: {=IF($H15="","",IFERROR(INDEX('Game Records'!$A:$A,$H15),""))} | D15: {=IF($H15="","",IFERROR(INDEX('Game Records'!$U:$U,$H15),""))} | E15: {=IF($H15="","",LET(r,$H15,mode,LOWER(INDEX('Game Records'!$D:$D,r)&""),endDate,INDEX('Game Records'!$C:$C,r),IF(mode="estimate",IF(endDate="","Estimate — End Date missing",IF(NOT(ISNUMBER(endDate)),"Estimate — Check End Date",IF(INT(endDate)>=TODAY(),"In Progress — ends "&TEXT(endDate,"mmm d, yyyy"),"Ready to Finalize"))),IF($F15="","No Highlighted Fields","Highlighted Fields Present"))))} | F15: {=IF($H15="","",IF(OR(NOT(_xlfn.ISFORMULA(INDEX('Game Records'!$N:$N,$H15))),NOT(_xlfn.ISFORMULA(INDEX('Game Records'!$O:$O,$H15))),NOT(_xlfn.ISFORMULA(INDEX('Game Records'!$P:$P,$H15))),NOT(_xlfn.ISFORMULA(INDEX('Game Records'!$Q:$Q,$H15))),NOT(_xlfn.ISFORMULA(INDEX('Game Records'!$R:$R,$H15))),NOT(_xlfn.ISFORMULA(INDEX('Game Records'!$S:$S,$H15))),NOT(_xlfn.ISFORMULA(INDEX('Game Records'!$T:$T,$H15))),NOT(_xlfn.ISFORMULA(INDEX('Game Records'!$U:$U,$H15))),NOT(_xlfn.ISFORMULA(INDEX('Game Records'!$V:$V,$H15))),NOT(_xlfn.ISFORMULA(INDEX('Game Records'!$W:$W,$H15))),NOT(_xlfn.ISFORMULA(INDEX('Game Records'!$X:$X,$H15))),NOT(_xlfn.ISFORMULA(INDEX('Game Records'!$Y:$Y,$H15))),NOT(_xlfn.ISFORMULA(INDEX('Game Records'!$Z:$Z,$H15)))),"","")&IF(INDEX('Game Records'!$B:$B,$H15)="","Start Date; ","")&IF(INDEX('Game Records'!$C:$C,$H15)="","End Date; ","")&IF(AND(INDEX('Game Records'!$U:$U,$H15)<>"Subscription",INDEX('Game Records'!$U:$U,$H15)<>"Free Game",INDEX('Game Records'!$U:$U,$H15)<>"Disqualified — Free Game",OR(INDEX('Game Records'!$D:$D,$H15)="",LOWER(INDEX('Game Records'!$D:$D,$H15)&"")="n/a")),"Entry Mode; ","")&IF(AND(INDEX('Game Records'!$U:$U,$H15)<>"Subscription",INDEX('Game Records'!$U:$U,$H15)<>"Free Game",INDEX('Game Records'!$U:$U,$H15)<>"Disqualified — Free Game",OR(INDEX('Game Records'!$E:$E,$H15)="",LOWER(INDEX('Game Records'!$E:$E,$H15)&"")="n/a")),"Game Type; ","")&IF(INDEX('Game Records'!$F:$F,$H15)="","Payment Type; ","")&IF(AND(INDEX('Game Records'!$U:$U,$H15)<>"Subscription",INDEX('Game Records'!$U:$U,$H15)<>"Free Game",INDEX('Game Records'!$U:$U,$H15)<>"Disqualified — Free Game",INDEX('Game Records'!$G:$G,$H15)=""),"Gross Pot; ","")&IF(AND(INDEX('Game Records'!$U:$U,$H15)<>"Free Game",INDEX('Game Records'!$U:$U,$H15)<>"Disqualified — Free Game",INDEX('Game Records'!$H:$H,$H15)=""),"Entry Fee; ","")&IF(AND(INDEX('Game Records'!$U:$U,$H15)<>"Subscription",INDEX('Game Records'!$U:$U,$H15)<>"Free Game",INDEX('Game Records'!$U:$U,$H15)<>"Disqualified — Free Game",INDEX('Game Records'!$I:$I,$H15)=""),"Eligible Players; ","")&IF(AND(INDEX('Game Records'!$U:$U,$H15)<>"Subscription",INDEX('Game Records'!$U:$U,$H15)<>"Free Game",INDEX('Game Records'!$U:$U,$H15)<>"Disqualified — Free Game",INDEX('Game Records'!$J:$J,$H15)=""),"Total Players; ","")&IF(AND(LOWER(INDEX('Game Records'!$D:$D,$H15)&"")="finalized",LOWER(INDEX('Game Records'!$L:$L,$H15)&"")<>"yes",INDEX('Game Records'!$U:$U,$H15)<>"Subscription",INDEX('Game Records'!$U:$U,$H15)<>"Free Game",INDEX('Game Records'!$U:$U,$H15)<>"Disqualified — Free Game",INDEX('Game Records'!$K:$K,$H15)=""),"Final Payout; ","")&IF(AND(LOWER(INDEX('Game Records'!$D:$D,$H15)&"")="finalized",INDEX('Game Records'!$U:$U,$H15)<>"Subscription",INDEX('Game Records'!$U:$U,$H15)<>"Free Game",INDEX('Game Records'!$U:$U,$H15)<>"Disqualified — Free Game",OR(INDEX('Game Records'!$L:$L,$H15)="",LOWER(INDEX('Game Records'!$L:$L,$H15)&"")="n/a")),"Disqualified Status; ",""))} | G15: {=IF($H15="","",IFERROR(INDEX('Game Records'!$M:$M,$H15),""))} | I15: Estimate Date Issues | J15: =COUNTIF($E$5:$E$504,"Estimate — *End Date*") -> 0
A16: =IF($H16="","",ROWS($A$5:A16)) | B16: =IF($H16="","","G-"&TEXT($A16,"0000")) | C16: {=IF($H16="","",IFERROR(INDEX('Game Records'!$A:$A,$H16),""))} | D16: {=IF($H16="","",IFERROR(INDEX('Game Records'!$U:$U,$H16),""))} | E16: {=IF($H16="","",LET(r,$H16,mode,LOWER(INDEX('Game Records'!$D:$D,r)&""),endDate,INDEX('Game Records'!$C:$C,r),IF(mode="estimate",IF(endDate="","Estimate — End Date missing",IF(NOT(ISNUMBER(endDate)),"Estimate — Check End Date",IF(INT(endDate)>=TODAY(),"In Progress — ends "&TEXT(endDate,"mmm d, yyyy"),"Ready to Finalize"))),IF($F16="","No Highlighted Fields","Highlighted Fields Present"))))} | F16: {=IF($H16="","",IF(OR(NOT(_xlfn.ISFORMULA(INDEX('Game Records'!$N:$N,$H16))),NOT(_xlfn.ISFORMULA(INDEX('Game Records'!$O:$O,$H16))),NOT(_xlfn.ISFORMULA(INDEX('Game Records'!$P:$P,$H16))),NOT(_xlfn.ISFORMULA(INDEX('Game Records'!$Q:$Q,$H16))),NOT(_xlfn.ISFORMULA(INDEX('Game Records'!$R:$R,$H16))),NOT(_xlfn.ISFORMULA(INDEX('Game Records'!$S:$S,$H16))),NOT(_xlfn.ISFORMULA(INDEX('Game Records'!$T:$T,$H16))),NOT(_xlfn.ISFORMULA(INDEX('Game Records'!$U:$U,$H16))),NOT(_xlfn.ISFORMULA(INDEX('Game Records'!$V:$V,$H16))),NOT(_xlfn.ISFORMULA(INDEX('Game Records'!$W:$W,$H16))),NOT(_xlfn.ISFORMULA(INDEX('Game Records'!$X:$X,$H16))),NOT(_xlfn.ISFORMULA(INDEX('Game Records'!$Y:$Y,$H16))),NOT(_xlfn.ISFORMULA(INDEX('Game Records'!$Z:$Z,$H16)))),"","")&IF(INDEX('Game Records'!$B:$B,$H16)="","Start Date; ","")&IF(INDEX('Game Records'!$C:$C,$H16)="","End Date; ","")&IF(AND(INDEX('Game Records'!$U:$U,$H16)<>"Subscription",INDEX('Game Records'!$U:$U,$H16)<>"Free Game",INDEX('Game Records'!$U:$U,$H16)<>"Disqualified — Free Game",OR(INDEX('Game Records'!$D:$D,$H16)="",LOWER(INDEX('Game Records'!$D:$D,$H16)&"")="n/a")),"Entry Mode; ","")&IF(AND(INDEX('Game Records'!$U:$U,$H16)<>"Subscription",INDEX('Game Records'!$U:$U,$H16)<>"Free Game",INDEX('Game Records'!$U:$U,$H16)<>"Disqualified — Free Game",OR(INDEX('Game Records'!$E:$E,$H16)="",LOWER(INDEX('Game Records'!$E:$E,$H16)&"")="n/a")),"Game Type; ","")&IF(INDEX('Game Records'!$F:$F,$H16)="","Payment Type; ","")&IF(AND(INDEX('Game Records'!$U:$U,$H16)<>"Subscription",INDEX('Game Records'!$U:$U,$H16)<>"Free Game",INDEX('Game Records'!$U:$U,$H16)<>"Disqualified — Free Game",INDEX('Game Records'!$G:$G,$H16)=""),"Gross Pot; ","")&IF(AND(INDEX('Game Records'!$U:$U,$H16)<>"Free Game",INDEX('Game Records'!$U:$U,$H16)<>"Disqualified — Free Game",INDEX('Game Records'!$H:$H,$H16)=""),"Entry Fee; ","")&IF(AND(INDEX('Game Records'!$U:$U,$H16)<>"Subscription",INDEX('Game Records'!$U:$U,$H16)<>"Free Game",INDEX('Game Records'!$U:$U,$H16)<>"Disqualified — Free Game",INDEX('Game Records'!$I:$I,$H16)=""),"Eligible Players; ","")&IF(AND(INDEX('Game Records'!$U:$U,$H16)<>"Subscription",INDEX('Game Records'!$U:$U,$H16)<>"Free Game",INDEX('Game Records'!$U:$U,$H16)<>"Disqualified — Free Game",INDEX('Game Records'!$J:$J,$H16)=""),"Total Players; ","")&IF(AND(LOWER(INDEX('Game Records'!$D:$D,$H16)&"")="finalized",LOWER(INDEX('Game Records'!$L:$L,$H16)&"")<>"yes",INDEX('Game Records'!$U:$U,$H16)<>"Subscription",INDEX('Game Records'!$U:$U,$H16)<>"Free Game",INDEX('Game Records'!$U:$U,$H16)<>"Disqualified — Free Game",INDEX('Game Records'!$K:$K,$H16)=""),"Final Payout; ","")&IF(AND(LOWER(INDEX('Game Records'!$D:$D,$H16)&"")="finalized",INDEX('Game Records'!$U:$U,$H16)<>"Subscription",INDEX('Game Records'!$U:$U,$H16)<>"Free Game",INDEX('Game Records'!$U:$U,$H16)<>"Disqualified — Free Game",OR(INDEX('Game Records'!$L:$L,$H16)="",LOWER(INDEX('Game Records'!$L:$L,$H16)&"")="n/a")),"Disqualified Status; ",""))} | G16: {=IF($H16="","",IFERROR(INDEX('Game Records'!$M:$M,$H16),""))}
