Workbook

Sheet Instructions
A1: StepCat Workbook Instructions — v252
A2: Use this sheet as the reference for entering records, carrying totals forward, and understanding calculations.
A3: Start here | B3: Enter or paste each new record in a prepared Game Records row beginning with A5. In Microsoft Excel, a forgotten game may also be added directly above or below an existing game by choosing Insert Table Rows Above/Below inside the Game Records table. Paste while the column-A cell is selected, not while a text cursor is editing inside the cell.
A4: Editable columns | B4: Use columns A–M for record information. Columns N–Z contain formulas and update automatically in prepared rows and in Excel table rows inserted inside Game Records.
A5: Calculation fields | B5: Use the fields that apply to the selected Estimate or Finalized mode. Estimate records are projections only; their accounting columns remain N/A and cash totals do not change until the same row is Finalized. Other fields may remain blank when they do not apply.
A6: Yellow input cells | B6: All A:M input cells are yellow because they are editable. They remain yellow whether blank or filled.
A7: Record Review | B7: Record Review is formula-driven and should not be edited directly. Enter or revise records only in Game Records A–M. It assigns each non-subscription game a Game # and Game Records ID, shows the calculated result, review flags, and Notes. Prepared rows may remain blank until a matching game exists. Selecting a cell may show its formula in the formula bar; this is normal. Formula text should not appear as the displayed cell value.
A8: Profit rule | B8: Profit means Result Earned is above Entry Fee.
A9: Draw rule | B9: A finalized paid game earning the Entry Fee or less is treated as a Draw with $0.00 net profit. Estimate rows preserve the exact projection but do not post Profit, Draw, Lost, ROI, or Net Profit accounting until finalized.
A10: Loss rule | B10: A monetary loss occurs only when Disqualified / Lost Entry Fee is Yes on a paid entry; the full Entry Fee is counted as lost.
A11: Subscriptions | B11: For the annual platform membership, select “Subscription — membership charge only” and enter the annual cost in Entry Fee. This is a non-game expense and must not be used for a free-entry challenge.
A12: Free games | B12: Select “Free Game — completed challenge/chips” for a completed free-entry challenge or a record that awards chips/game credit. Enter chips in Final Earned / Chips when known. When the estimate inputs are unavailable, Adjusted Pot / Chips and Estimated Earned / Chips display N/A instead of an error or misleading zero.
A13: Summary | B13: Summary uses exact counts and cash totals. Free Games are shown separately from paid-game Profit, Draw, and Disqualified counts, and their chips are reported in a separate non-cash total.
A14: Game Comparisons | B14: The paid table compares Member, Non-Member, Unclassified, and All Paid Games. A separate Free Game Chip Performance section shows completed, disqualified, chips-earned, eliminated-player, and elimination-rate statistics. Subscription rows are excluded.
... A28: Carryover | B28: Enter prior totals once, then continue with only new records.
A29: Prior Net Game Profit | B29: 0
A30: Prior Subscription Costs | B30: 0
A31: Prior Game Count | B31: 0
A32: Step 1 — Note prior totals | B32: Open the completed or archived workbook and note its ending Net Game Profit, subscription costs already paid, and completed-game count.
A33: Step 2 — Enter once | B33: Enter those three figures once in B29:B31. Do not create Game Records rows for the carryover values.
A34: Step 3 — Continue records | B34: Begin new records on Game Records row 5. Enter only activity that occurred after the previous workbook ended.
A35: Step 4 — Check totals | B35: Running totals and Summary should begin with the carryover figures and then add the new workbook's records.
A36: Important | B36: Use Carryover only when continuing from another workbook or starting partway through a year. Prior Game Count includes finalized completed games only; exclude Subscription rows and Estimate rows. Do not re-enter prior games or prior subscription payments.
A38: Calculations | B38: Reference for how the workbook determines results and totals.
A39: Member games | B39: Adjusted Pot uses 100% of Gross Pot.
A40: Non-Member games | B40: Adjusted Pot uses 85% of Gross Pot.
A41: Estimated Earned | B41: Adjusted Pot divided by Eligible Players. This is a projection only. On Estimate rows, Result Earned / Chips, Profit, Draw, Lost Entry Fee, ROI, and Net Profit show N/A; Result shows Estimate; Running Net Profit remains unchanged. When the game ends, replace the same row’s A–M values with the Finalized record—do not add a second row for that game.
A42: Profit | B42: On Finalized rows, Result Earned above Entry Fee is Profit; Net Profit is Result Earned minus Entry Fee. Estimate rows remain outside accounting until finalized.
A44: Draw | B44: A normal completed paid game earning the Entry Fee or less records $0.00 Net Profit while preserving the exact Estimated Earned or Final Earned amount.
A45: Disqualified | B45: Paid entry: Final Earned / Chips and Result Earned / Chips should show $0.00, and the full Entry Fee is recorded as lost. Free Game: the disqualification status is preserved, 0.00 chips are earned, and no monetary Entry Fee loss is recorded.
... A65: v252 release checklist | B65: Regression-test Start New Entry, Finalize This Estimate, remembered choices, changed validation, a complete A–M row paste, Estimate-to-Finalized row replacement, and hosted installation/update behavior.

Sheet Game Records
A1: ="Running Net Game Profit: "&TEXT(Instructions!$B$29+SUM($W$5:$W$504),"$#,##0.00")&" | Gross Profit Earned: "&TEXT(SUM($Q$5:$Q$504),"$#,##0.00")&" | Total Lost Entry Fees: "&TEXT(SUM($S$5:$S$504),"$#,##0.00")&" | StepCat v252"
A2: Rows 5–504 are prepared. Enter or paste only in A:M; N:Z calculate automatically. Estimate rows remain projections: accounting columns show N/A and cash totals do not change until the same row is Finalized. Archive at row 505.
A3: A:M — Inputs only | N3: N:Z — Formula columns — do not edit
A4: Game Name | B4: Start Date | C4: End Date | D4: Entry Mode | E4: Game Type | F4: Payment / Record Type | G4: Gross Pot / Chips | H4: Entry Fee | I4: Eligible Players | J4: Total Players | K4: Final Earned / Chips | L4: Disqualified / Lost Entry Fee | M4: Notes | N4: Adjusted Pot / Chips | O4: Estimated Earned / Chips | P4: Result Earned / Chips | Q4: Profit | R4: Draw | S4: Lost | T4: ROI | U4: Result | V4: Challenge Length (Weeks) | W4: Net Profit | X4: Eliminated Players | Y4: Elimination Rate | Z4: Running Net Profit
N5: =IF(COUNTA($A5:$M5)=0,"",IF(OR(LEFT(LOWER(TRIM($F5&"")),12)="subscription",LOWER(TRIM($F5&""))="membership"),"",IF(OR(AND($H5<>"",$H5=0),LEFT(LOWER(TRIM($F5&"")),9)="free game",LOWER(TRIM($F5&""))="free",LOWER(TRIM($F5&""))="free entry"),IF(ISNUMBER($G5),IF(ISNUMBER(SEARCH("non",LOWER($E5&""))),$G5*0.85,$G5),"N/A"),IF($G5="","",IFERROR(IF(ISNUMBER(SEARCH("non",LOWER($E5&""))),$G5*0.85,$G5),""))))) | O5: =IF(COUNTA($A5:$M5)=0,"",IF(OR(LEFT(LOWER(TRIM($F5&"")),12)="subscription",LOWER(TRIM($F5&""))="membership"),"",IF(OR(AND($H5<>"",$H5=0),LEFT(LOWER(TRIM($F5&"")),9)="free game",LOWER(TRIM($F5&""))="free",LOWER(TRIM($F5&""))="free entry"),IF(OR(NOT(ISNUMBER($N5)),NOT(ISNUMBER($I5)),$I5=0),"N/A",IFERROR($N5/$I5,"N/A")),IF(OR($N5="",$I5="",$I5=0),"",IFERROR($N5/$I5,""))))) | P5: =IF(COUNTA($A5:$M5)=0,"",IF(OR(LEFT(LOWER(TRIM($F5&"")),12)="subscription",LOWER(TRIM($F5&""))="membership"),"",IF(LOWER(TRIM($D5&""))="estimate","N/A",IF(LOWER($L5&"")="yes",0,IF(OR(AND($H5<>"",$H5=0),LEFT(LOWER(TRIM($F5&"")),9)="free game",LOWER(TRIM($F5&""))="free",LOWER(TRIM($F5&""))="free entry"),IF(ISNUMBER($K5),$K5,""),IF($K5<>"",$K5,"")))))) | Q5: =IF(COUNTA($A5:$M5)=0,"",IF(OR($U5="Subscription",$U5=""),"",IF($U5="Estimate","N/A",IF($U5="Profit",ROUND(IFERROR($P5,0)-IFERROR($H5,0),2),0)))) | R5: =IF(COUNTA($A5:$M5)=0,"",IF(OR($U5="Subscription",$U5=""),"",IF($U5="Estimate","N/A",IF($U5="Draw",$H5,0)))) | S5: =IF(COUNTA($A5:$M5)=0,"",IF(OR($U5="Subscription",$U5=""),"",IF($U5="Estimate","N/A",IF($U5="Disqualified",$H5,0)))) | T5: =IF(COUNTA($A5:$M5)=0,"",IF(OR($U5="Subscription",$U5=""),"",IF($U5="Estimate","N/A",IF(OR($U5="Free Game",$U5="Disqualified — Free Game",$H5=0),"N/A",IF($U5="Profit",$Q5/$H5,IF($U5="Disqualified",-$S5/$H5,0)))))) | U5: =IF(COUNTA($A5:$M5)=0,"",IF(OR(LEFT(LOWER(TRIM($F5&"")),12)="subscription",LOWER(TRIM($F5&""))="membership"),"Subscription",IF(LOWER(TRIM($D5&""))="estimate","Estimate",IF(OR(AND($H5<>"",$H5=0),LEFT(LOWER(TRIM($F5&"")),9)="free game",LOWER(TRIM($F5&""))="free",LOWER(TRIM($F5&""))="free entry"),IF(LOWER($L5&"")="yes","Disqualified — Free Game","Free Game"),IF(LOWER($L5&"")="yes","Disqualified",IF($P5="","",IF(ROUND(IFERROR(VALUE($P5),0)-IFERROR(VALUE($H5),0),2)>0,"Profit","Draw"))))))) | V5: =IF(COUNTA($A5:$M5)=0,"",IF(OR($B5="",$C5="",$U5="Subscription"),"",IFERROR(ROUNDUP(($C5-$B5)/7,0),""))) | W5: =IF(COUNTA($A5:$M5)=0,"",IF(OR($U5="Subscription",$U5=""),"",IF($U5="Estimate","N/A",IF(OR($U5="Free Game",$U5="Disqualified — Free Game"),0,ROUND(IFERROR($Q5,0)-IFERROR($S5,0),2))))) | X5: =IF(COUNTA($A5:$M5)=0,"",IF(OR($U5="Subscription",NOT(ISNUMBER($J5)),NOT(ISNUMBER($I5)),$J5=0,$I5=0,$I5>$J5),"",$J5-$I5)) | Y5: =IF(COUNTA($A5:$M5)=0,"",IF(OR($U5="Subscription",NOT(ISNUMBER($J5)),$J5=0,$X5=""),"",$X5/$J5)) | Z5: =IF(COUNTA($A5:$M5)=0,"",Instructions!$B$29+SUM($W$5:W5))
N6: =IF(COUNTA($A6:$M6)=0,"",IF(OR(LEFT(LOWER(TRIM($F6&"")),12)="subscription",LOWER(TRIM($F6&""))="membership"),"",IF(OR(AND($H6<>"",$H6=0),LEFT(LOWER(TRIM($F6&"")),9)="free game",LOWER(TRIM($F6&""))="free",LOWER(TRIM($F6&""))="free entry"),IF(ISNUMBER($G6),IF(ISNUMBER(SEARCH("non",LOWER($E6&""))),$G6*0.85,$G6),"N/A"),IF($G6="","",IFERROR(IF(ISNUMBER(SEARCH("non",LOWER($E6&""))),$G6*0.85,$G6),""))))) | O6: =IF(COUNTA($A6:$M6)=0,"",IF(OR(LEFT(LOWER(TRIM($F6&"")),12)="subscription",LOWER(TRIM($F6&""))="membership"),"",IF(OR(AND($H6<>"",$H6=0),LEFT(LOWER(TRIM($F6&"")),9)="free game",LOWER(TRIM($F6&""))="free",LOWER(TRIM($F6&""))="free entry"),IF(OR(NOT(ISNUMBER($N6)),NOT(ISNUMBER($I6)),$I6=0),"N/A",IFERROR($N6/$I6,"N/A")),IF(OR($N6="",$I6="",$I6=0),"",IFERROR($N6/$I6,""))))) | P6: =IF(COUNTA($A6:$M6)=0,"",IF(OR(LEFT(LOWER(TRIM($F6&"")),12)="subscription",LOWER(TRIM($F6&""))="membership"),"",IF(LOWER(TRIM($D6&""))="estimate","N/A",IF(LOWER($L6&"")="yes",0,IF(OR(AND($H6<>"",$H6=0),LEFT(LOWER(TRIM($F6&"")),9)="free game",LOWER(TRIM($F6&""))="free",LOWER(TRIM($F6&""))="free entry"),IF(ISNUMBER($K6),$K6,""),IF($K6<>"",$K6,"")))))) | Q6: =IF(COUNTA($A6:$M6)=0,"",IF(OR($U6="Subscription",$U6=""),"",IF($U6="Estimate","N/A",IF($U6="Profit",ROUND(IFERROR($P6,0)-IFERROR($H6,0),2),0)))) | R6: =IF(COUNTA($A6:$M6)=0,"",IF(OR($U6="Subscription",$U6=""),"",IF($U6="Estimate","N/A",IF($U6="Draw",$H6,0)))) | S6: =IF(COUNTA($A6:$M6)=0,"",IF(OR($U6="Subscription",$U6=""),"",IF($U6="Estimate","N/A",IF($U6="Disqualified",$H6,0)))) | T6: =IF(COUNTA($A6:$M6)=0,"",IF(OR($U6="Subscription",$U6=""),"",IF($U6="Estimate","N/A",IF(OR($U6="Free Game",$U6="Disqualified — Free Game",$H6=0),"N/A",IF($U6="Profit",$Q6/$H6,IF($U6="Disqualified",-$S6/$H6,0)))))) | U6: =IF(COUNTA($A6:$M6)=0,"",IF(OR(LEFT(LOWER(TRIM($F6&"")),12)="subscription",LOWER(TRIM($F6&""))="membership"),"Subscription",IF(LOWER(TRIM($D6&""))="estimate","Estimate",IF(OR(AND($H6<>"",$H6=0),LEFT(LOWER(TRIM($F6&"")),9)="free game",LOWER(TRIM($F6&""))="free",LOWER(TRIM($F6&""))="free entry"),IF(LOWER($L6&"")="yes","Disqualified — Free Game","Free Game"),IF(LOWER($L6&"")="yes","Disqualified",IF($P6="","",IF(ROUND(IFERROR(VALUE($P6),0)-IFERROR(VALUE($H6),0),2)>0,"Profit","Draw"))))))) | V6: =IF(COUNTA($A6:$M6)=0,"",IF(OR($B6="",$C6="",$U6="Subscription"),"",IFERROR(ROUNDUP(($C6-$B6)/7,0),""))) | W6: =IF(COUNTA($A6:$M6)=0,"",IF(OR($U6="Subscription",$U6=""),"",IF($U6="Estimate","N/A",IF(OR($U6="Free Game",$U6="Disqualified — Free Game"),0,ROUND(IFERROR($Q6,0)-IFERROR($S6,0),2))))) | X6: =IF(COUNTA($A6:$M6)=0,"",IF(OR($U6="Subscription",NOT(ISNUMBER($J6)),NOT(ISNUMBER($I6)),$J6=0,$I6=0,$I6>$J6),"",$J6-$I6)) | Y6: =IF(COUNTA($A6:$M6)=0,"",IF(OR($U6="Subscription",NOT(ISNUMBER($J6)),$J6=0,$X6=""),"",$X6/$J6)) | Z6: =IF(COUNTA($A6:$M6)=0,"",Instructions!$B$29+SUM($W$5:W6))
N7: =IF(COUNTA($A7:$M7)=0,"",IF(OR(LEFT(LOWER(TRIM($F7&"")),12)="subscription",LOWER(TRIM($F7&""))="membership"),"",IF(OR(AND($H7<>"",$H7=0),LEFT(LOWER(TRIM($F7&"")),9)="free game",LOWER(TRIM($F7&""))="free",LOWER(TRIM($F7&""))="free entry"),IF(ISNUMBER($G7),IF(ISNUMBER(SEARCH("non",LOWER($E7&""))),$G7*0.85,$G7),"N/A"),IF($G7="","",IFERROR(IF(ISNUMBER(SEARCH("non",LOWER($E7&""))),$G7*0.85,$G7),""))))) | O7: =IF(COUNTA($A7:$M7)=0,"",IF(OR(LEFT(LOWER(TRIM($F7&"")),12)="subscription",LOWER(TRIM($F7&""))="membership"),"",IF(OR(AND($H7<>"",$H7=0),LEFT(LOWER(TRIM($F7&"")),9)="free game",LOWER(TRIM($F7&""))="free",LOWER(TRIM($F7&""))="free entry"),IF(OR(NOT(ISNUMBER($N7)),NOT(ISNUMBER($I7)),$I7=0),"N/A",IFERROR($N7/$I7,"N/A")),IF(OR($N7="",$I7="",$I7=0),"",IFERROR($N7/$I7,""))))) | P7: =IF(COUNTA($A7:$M7)=0,"",IF(OR(LEFT(LOWER(TRIM($F7&"")),12)="subscription",LOWER(TRIM($F7&""))="membership"),"",IF(LOWER(TRIM($D7&""))="estimate","N/A",IF(LOWER($L7&"")="yes",0,IF(OR(AND($H7<>"",$H7=0),LEFT(LOWER(TRIM($F7&"")),9)="free game",LOWER(TRIM($F7&""))="free",LOWER(TRIM($F7&""))="free entry"),IF(ISNUMBER($K7),$K7,""),IF($K7<>"",$K7,"")))))) | Q7: =IF(COUNTA($A7:$M7)=0,"",IF(OR($U7="Subscription",$U7=""),"",IF($U7="Estimate","N/A",IF($U7="Profit",ROUND(IFERROR($P7,0)-IFERROR($H7,0),2),0)))) | R7: =IF(COUNTA($A7:$M7)=0,"",IF(OR($U7="Subscription",$U7=""),"",IF($U7="Estimate","N/A",IF($U7="Draw",$H7,0)))) | S7: =IF(COUNTA($A7:$M7)=0,"",IF(OR($U7="Subscription",$U7=""),"",IF($U7="Estimate","N/A",IF($U7="Disqualified",$H7,0)))) | T7: =IF(COUNTA($A7:$M7)=0,"",IF(OR($U7="Subscription",$U7=""),"",IF($U7="Estimate","N/A",IF(OR($U7="Free Game",$U7="Disqualified — Free Game",$H7=0),"N/A",IF($U7="Profit",$Q7/$H7,IF($U7="Disqualified",-$S7/$H7,0)))))) | U7: =IF(COUNTA($A7:$M7)=0,"",IF(OR(LEFT(LOWER(TRIM($F7&"")),12)="subscription",LOWER(TRIM($F7&""))="membership"),"Subscription",IF(LOWER(TRIM($D7&""))="estimate","Estimate",IF(OR(AND($H7<>"",$H7=0),LEFT(LOWER(TRIM($F7&"")),9)="free game",LOWER(TRIM($F7&""))="free",LOWER(TRIM($F7&""))="free entry"),IF(LOWER($L7&"")="yes","Disqualified — Free Game","Free Game"),IF(LOWER($L7&"")="yes","Disqualified",IF($P7="","",IF(ROUND(IFERROR(VALUE($P7),0)-IFERROR(VALUE($H7),0),2)>0,"Profit","Draw"))))))) | V7: =IF(COUNTA($A7:$M7)=0,"",IF(OR($B7="",$C7="",$U7="Subscription"),"",IFERROR(ROUNDUP(($C7-$B7)/7,0),""))) | W7: =IF(COUNTA($A7:$M7)=0,"",IF(OR($U7="Subscription",$U7=""),"",IF($U7="Estimate","N/A",IF(OR($U7="Free Game",$U7="Disqualified — Free Game"),0,ROUND(IFERROR($Q7,0)-IFERROR($S7,0),2))))) | X7: =IF(COUNTA($A7:$M7)=0,"",IF(OR($U7="Subscription",NOT(ISNUMBER($J7)),NOT(ISNUMBER($I7)),$J7=0,$I7=0,$I7>$J7),"",$J7-$I7)) | Y7: =IF(COUNTA($A7:$M7)=0,"",IF(OR($U7="Subscription",NOT(ISNUMBER($J7)),$J7=0,$X7=""),"",$X7/$J7)) | Z7: =IF(COUNTA($A7:$M7)=0,"",Instructions!$B$29+SUM($W$5:W7))
N8: =IF(COUNTA($A8:$M8)=0,"",IF(OR(LEFT(LOWER(TRIM($F8&"")),12)="subscription",LOWER(TRIM($F8&""))="membership"),"",IF(OR(AND($H8<>"",$H8=0),LEFT(LOWER(TRIM($F8&"")),9)="free game",LOWER(TRIM($F8&""))="free",LOWER(TRIM($F8&""))="free entry"),IF(ISNUMBER($G8),IF(ISNUMBER(SEARCH("non",LOWER($E8&""))),$G8*0.85,$G8),"N/A"),IF($G8="","",IFERROR(IF(ISNUMBER(SEARCH("non",LOWER($E8&""))),$G8*0.85,$G8),""))))) | O8: =IF(COUNTA($A8:$M8)=0,"",IF(OR(LEFT(LOWER(TRIM($F8&"")),12)="subscription",LOWER(TRIM($F8&""))="membership"),"",IF(OR(AND($H8<>"",$H8=0),LEFT(LOWER(TRIM($F8&"")),9)="free game",LOWER(TRIM($F8&""))="free",LOWER(TRIM($F8&""))="free entry"),IF(OR(NOT(ISNUMBER($N8)),NOT(ISNUMBER($I8)),$I8=0),"N/A",IFERROR($N8/$I8,"N/A")),IF(OR($N8="",$I8="",$I8=0),"",IFERROR($N8/$I8,""))))) | P8: =IF(COUNTA($A8:$M8)=0,"",IF(OR(LEFT(LOWER(TRIM($F8&"")),12)="subscription",LOWER(TRIM($F8&""))="membership"),"",IF(LOWER(TRIM($D8&""))="estimate","N/A",IF(LOWER($L8&"")="yes",0,IF(OR(AND($H8<>"",$H8=0),LEFT(LOWER(TRIM($F8&"")),9)="free game",LOWER(TRIM($F8&""))="free",LOWER(TRIM($F8&""))="free entry"),IF(ISNUMBER($K8),$K8,""),IF($K8<>"",$K8,"")))))) | Q8: =IF(COUNTA($A8:$M8)=0,"",IF(OR($U8="Subscription",$U8=""),"",IF($U8="Estimate","N/A",IF($U8="Profit",ROUND(IFERROR($P8,0)-IFERROR($H8,0),2),0)))) | R8: =IF(COUNTA($A8:$M8)=0,"",IF(OR($U8="Subscription",$U8=""),"",IF($U8="Estimate","N/A",IF($U8="Draw",$H8,0)))) | S8: =IF(COUNTA($A8:$M8)=0,"",IF(OR($U8="Subscription",$U8=""),"",IF($U8="Estimate","N/A",IF($U8="Disqualified",$H8,0)))) | T8: =IF(COUNTA($A8:$M8)=0,"",IF(OR($U8="Subscription",$U8=""),"",IF($U8="Estimate","N/A",IF(OR($U8="Free Game",$U8="Disqualified — Free Game",$H8=0),"N/A",IF($U8="Profit",$Q8/$H8,IF($U8="Disqualified",-$S8/$H8,0)))))) | U8: =IF(COUNTA($A8:$M8)=0,"",IF(OR(LEFT(LOWER(TRIM($F8&"")),12)="subscription",LOWER(TRIM($F8&""))="membership"),"Subscription",IF(LOWER(TRIM($D8&""))="estimate","Estimate",IF(OR(AND($H8<>"",$H8=0),LEFT(LOWER(TRIM($F8&"")),9)="free game",LOWER(TRIM($F8&""))="free",LOWER(TRIM($F8&""))="free entry"),IF(LOWER($L8&"")="yes","Disqualified — Free Game","Free Game"),IF(LOWER($L8&"")="yes","Disqualified",IF($P8="","",IF(ROUND(IFERROR(VALUE($P8),0)-IFERROR(VALUE($H8),0),2)>0,"Profit","Draw"))))))) | V8: =IF(COUNTA($A8:$M8)=0,"",IF(OR($B8="",$C8="",$U8="Subscription"),"",IFERROR(ROUNDUP(($C8-$B8)/7,0),""))) | W8: =IF(COUNTA($A8:$M8)=0,"",IF(OR($U8="Subscription",$U8=""),"",IF($U8="Estimate","N/A",IF(OR($U8="Free Game",$U8="Disqualified — Free Game"),0,ROUND(IFERROR($Q8,0)-IFERROR($S8,0),2))))) | X8: =IF(COUNTA($A8:$M8)=0,"",IF(OR($U8="Subscription",NOT(ISNUMBER($J8)),NOT(ISNUMBER($I8)),$J8=0,$I8=0,$I8>$J8),"",$J8-$I8)) | Y8: =IF(COUNTA($A8:$M8)=0,"",IF(OR($U8="Subscription",NOT(ISNUMBER($J8)),$J8=0,$X8=""),"",$X8/$J8)) | Z8: =IF(COUNTA($A8:$M8)=0,"",Instructions!$B$29+SUM($W$5:W8))
N9: =IF(COUNTA($A9:$M9)=0,"",IF(OR(LEFT(LOWER(TRIM($F9&"")),12)="subscription",LOWER(TRIM($F9&""))="membership"),"",IF(OR(AND($H9<>"",$H9=0),LEFT(LOWER(TRIM($F9&"")),9)="free game",LOWER(TRIM($F9&""))="free",LOWER(TRIM($F9&""))="free entry"),IF(ISNUMBER($G9),IF(ISNUMBER(SEARCH("non",LOWER($E9&""))),$G9*0.85,$G9),"N/A"),IF($G9="","",IFERROR(IF(ISNUMBER(SEARCH("non",LOWER($E9&""))),$G9*0.85,$G9),""))))) | O9: =IF(COUNTA($A9:$M9)=0,"",IF(OR(LEFT(LOWER(TRIM($F9&"")),12)="subscription",LOWER(TRIM($F9&""))="membership"),"",IF(OR(AND($H9<>"",$H9=0),LEFT(LOWER(TRIM($F9&"")),9)="free game",LOWER(TRIM($F9&""))="free",LOWER(TRIM($F9&""))="free entry"),IF(OR(NOT(ISNUMBER($N9)),NOT(ISNUMBER($I9)),$I9=0),"N/A",IFERROR($N9/$I9,"N/A")),IF(OR($N9="",$I9="",$I9=0),"",IFERROR($N9/$I9,""))))) | P9: =IF(COUNTA($A9:$M9)=0,"",IF(OR(LEFT(LOWER(TRIM($F9&"")),12)="subscription",LOWER(TRIM($F9&""))="membership"),"",IF(LOWER(TRIM($D9&""))="estimate","N/A",IF(LOWER($L9&"")="yes",0,IF(OR(AND($H9<>"",$H9=0),LEFT(LOWER(TRIM($F9&"")),9)="free game",LOWER(TRIM($F9&""))="free",LOWER(TRIM($F9&""))="free entry"),IF(ISNUMBER($K9),$K9,""),IF($K9<>"",$K9,"")))))) | Q9: =IF(COUNTA($A9:$M9)=0,"",IF(OR($U9="Subscription",$U9=""),"",IF($U9="Estimate","N/A",IF($U9="Profit",ROUND(IFERROR($P9,0)-IFERROR($H9,0),2),0)))) | R9: =IF(COUNTA($A9:$M9)=0,"",IF(OR($U9="Subscription",$U9=""),"",IF($U9="Estimate","N/A",IF($U9="Draw",$H9,0)))) | S9: =IF(COUNTA($A9:$M9)=0,"",IF(OR($U9="Subscription",$U9=""),"",IF($U9="Estimate","N/A",IF($U9="Disqualified",$H9,0)))) | T9: =IF(COUNTA($A9:$M9)=0,"",IF(OR($U9="Subscription",$U9=""),"",IF($U9="Estimate","N/A",IF(OR($U9="Free Game",$U9="Disqualified — Free Game",$H9=0),"N/A",IF($U9="Profit",$Q9/$H9,IF($U9="Disqualified",-$S9/$H9,0)))))) | U9: =IF(COUNTA($A9:$M9)=0,"",IF(OR(LEFT(LOWER(TRIM($F9&"")),12)="subscription",LOWER(TRIM($F9&""))="membership"),"Subscription",IF(LOWER(TRIM($D9&""))="estimate","Estimate",IF(OR(AND($H9<>"",$H9=0),LEFT(LOWER(TRIM($F9&"")),9)="free game",LOWER(TRIM($F9&""))="free",LOWER(TRIM($F9&""))="free entry"),IF(LOWER($L9&"")="yes","Disqualified — Free Game","Free Game"),IF(LOWER($L9&"")="yes","Disqualified",IF($P9="","",IF(ROUND(IFERROR(VALUE($P9),0)-IFERROR(VALUE($H9),0),2)>0,"Profit","Draw"))))))) | V9: =IF(COUNTA($A9:$M9)=0,"",IF(OR($B9="",$C9="",$U9="Subscription"),"",IFERROR(ROUNDUP(($C9-$B9)/7,0),""))) | W9: =IF(COUNTA($A9:$M9)=0,"",IF(OR($U9="Subscription",$U9=""),"",IF($U9="Estimate","N/A",IF(OR($U9="Free Game",$U9="Disqualified — Free Game"),0,ROUND(IFERROR($Q9,0)-IFERROR($S9,0),2))))) | X9: =IF(COUNTA($A9:$M9)=0,"",IF(OR($U9="Subscription",NOT(ISNUMBER($J9)),NOT(ISNUMBER($I9)),$J9=0,$I9=0,$I9>$J9),"",$J9-$I9)) | Y9: =IF(COUNTA($A9:$M9)=0,"",IF(OR($U9="Subscription",NOT(ISNUMBER($J9)),$J9=0,$X9=""),"",$X9/$J9)) | Z9: =IF(COUNTA($A9:$M9)=0,"",Instructions!$B$29+SUM($W$5:W9))
N10: =IF(COUNTA($A10:$M10)=0,"",IF(OR(LEFT(LOWER(TRIM($F10&"")),12)="subscription",LOWER(TRIM($F10&""))="membership"),"",IF(OR(AND($H10<>"",$H10=0),LEFT(LOWER(TRIM($F10&"")),9)="free game",LOWER(TRIM($F10&""))="free",LOWER(TRIM($F10&""))="free entry"),IF(ISNUMBER($G10),IF(ISNUMBER(SEARCH("non",LOWER($E10&""))),$G10*0.85,$G10),"N/A"),IF($G10="","",IFERROR(IF(ISNUMBER(SEARCH("non",LOWER($E10&""))),$G10*0.85,$G10),""))))) | O10: =IF(COUNTA($A10:$M10)=0,"",IF(OR(LEFT(LOWER(TRIM($F10&"")),12)="subscription",LOWER(TRIM($F10&""))="membership"),"",IF(OR(AND($H10<>"",$H10=0),LEFT(LOWER(TRIM($F10&"")),9)="free game",LOWER(TRIM($F10&""))="free",LOWER(TRIM($F10&""))="free entry"),IF(OR(NOT(ISNUMBER($N10)),NOT(ISNUMBER($I10)),$I10=0),"N/A",IFERROR($N10/$I10,"N/A")),IF(OR($N10="",$I10="",$I10=0),"",IFERROR($N10/$I10,""))))) | P10: =IF(COUNTA($A10:$M10)=0,"",IF(OR(LEFT(LOWER(TRIM($F10&"")),12)="subscription",LOWER(TRIM($F10&""))="membership"),"",IF(LOWER(TRIM($D10&""))="estimate","N/A",IF(LOWER($L10&"")="yes",0,IF(OR(AND($H10<>"",$H10=0),LEFT(LOWER(TRIM($F10&"")),9)="free game",LOWER(TRIM($F10&""))="free",LOWER(TRIM($F10&""))="free entry"),IF(ISNUMBER($K10),$K10,""),IF($K10<>"",$K10,"")))))) | Q10: =IF(COUNTA($A10:$M10)=0,"",IF(OR($U10="Subscription",$U10=""),"",IF($U10="Estimate","N/A",IF($U10="Profit",ROUND(IFERROR($P10,0)-IFERROR($H10,0),2),0)))) | R10: =IF(COUNTA($A10:$M10)=0,"",IF(OR($U10="Subscription",$U10=""),"",IF($U10="Estimate","N/A",IF($U10="Draw",$H10,0)))) | S10: =IF(COUNTA($A10:$M10)=0,"",IF(OR($U10="Subscription",$U10=""),"",IF($U10="Estimate","N/A",IF($U10="Disqualified",$H10,0)))) | T10: =IF(COUNTA($A10:$M10)=0,"",IF(OR($U10="Subscription",$U10=""),"",IF($U10="Estimate","N/A",IF(OR($U10="Free Game",$U10="Disqualified — Free Game",$H10=0),"N/A",IF($U10="Profit",$Q10/$H10,IF($U10="Disqualified",-$S10/$H10,0)))))) | U10: =IF(COUNTA($A10:$M10)=0,"",IF(OR(LEFT(LOWER(TRIM($F10&"")),12)="subscription",LOWER(TRIM($F10&""))="membership"),"Subscription",IF(LOWER(TRIM($D10&""))="estimate","Estimate",IF(OR(AND($H10<>"",$H10=0),LEFT(LOWER(TRIM($F10&"")),9)="free game",LOWER(TRIM($F10&""))="free",LOWER(TRIM($F10&""))="free entry"),IF(LOWER($L10&"")="yes","Disqualified — Free Game","Free Game"),IF(LOWER($L10&"")="yes","Disqualified",IF($P10="","",IF(ROUND(IFERROR(VALUE($P10),0)-IFERROR(VALUE($H10),0),2)>0,"Profit","Draw"))))))) | V10: =IF(COUNTA($A10:$M10)=0,"",IF(OR($B10="",$C10="",$U10="Subscription"),"",IFERROR(ROUNDUP(($C10-$B10)/7,0),""))) | W10: =IF(COUNTA($A10:$M10)=0,"",IF(OR($U10="Subscription",$U10=""),"",IF($U10="Estimate","N/A",IF(OR($U10="Free Game",$U10="Disqualified — Free Game"),0,ROUND(IFERROR($Q10,0)-IFERROR($S10,0),2))))) | X10: =IF(COUNTA($A10:$M10)=0,"",IF(OR($U10="Subscription",NOT(ISNUMBER($J10)),NOT(ISNUMBER($I10)),$J10=0,$I10=0,$I10>$J10),"",$J10-$I10)) | Y10: =IF(COUNTA($A10:$M10)=0,"",IF(OR($U10="Subscription",NOT(ISNUMBER($J10)),$J10=0,$X10=""),"",$X10/$J10)) | Z10: =IF(COUNTA($A10:$M10)=0,"",Instructions!$B$29+SUM($W$5:W10))
N11: =IF(COUNTA($A11:$M11)=0,"",IF(OR(LEFT(LOWER(TRIM($F11&"")),12)="subscription",LOWER(TRIM($F11&""))="membership"),"",IF(OR(AND($H11<>"",$H11=0),LEFT(LOWER(TRIM($F11&"")),9)="free game",LOWER(TRIM($F11&""))="free",LOWER(TRIM($F11&""))="free entry"),IF(ISNUMBER($G11),IF(ISNUMBER(SEARCH("non",LOWER($E11&""))),$G11*0.85,$G11),"N/A"),IF($G11="","",IFERROR(IF(ISNUMBER(SEARCH("non",LOWER($E11&""))),$G11*0.85,$G11),""))))) | O11: =IF(COUNTA($A11:$M11)=0,"",IF(OR(LEFT(LOWER(TRIM($F11&"")),12)="subscription",LOWER(TRIM($F11&""))="membership"),"",IF(OR(AND($H11<>"",$H11=0),LEFT(LOWER(TRIM($F11&"")),9)="free game",LOWER(TRIM($F11&""))="free",LOWER(TRIM($F11&""))="free entry"),IF(OR(NOT(ISNUMBER($N11)),NOT(ISNUMBER($I11)),$I11=0),"N/A",IFERROR($N11/$I11,"N/A")),IF(OR($N11="",$I11="",$I11=0),"",IFERROR($N11/$I11,""))))) | P11: =IF(COUNTA($A11:$M11)=0,"",IF(OR(LEFT(LOWER(TRIM($F11&"")),12)="subscription",LOWER(TRIM($F11&""))="membership"),"",IF(LOWER(TRIM($D11&""))="estimate","N/A",IF(LOWER($L11&"")="yes",0,IF(OR(AND($H11<>"",$H11=0),LEFT(LOWER(TRIM($F11&"")),9)="free game",LOWER(TRIM($F11&""))="free",LOWER(TRIM($F11&""))="free entry"),IF(ISNUMBER($K11),$K11,""),IF($K11<>"",$K11,"")))))) | Q11: =IF(COUNTA($A11:$M11)=0,"",IF(OR($U11="Subscription",$U11=""),"",IF($U11="Estimate","N/A",IF($U11="Profit",ROUND(IFERROR($P11,0)-IFERROR($H11,0),2),0)))) | R11: =IF(COUNTA($A11:$M11)=0,"",IF(OR($U11="Subscription",$U11=""),"",IF($U11="Estimate","N/A",IF($U11="Draw",$H11,0)))) | S11: =IF(COUNTA($A11:$M11)=0,"",IF(OR($U11="Subscription",$U11=""),"",IF($U11="Estimate","N/A",IF($U11="Disqualified",$H11,0)))) | T11: =IF(COUNTA($A11:$M11)=0,"",IF(OR($U11="Subscription",$U11=""),"",IF($U11="Estimate","N/A",IF(OR($U11="Free Game",$U11="Disqualified — Free Game",$H11=0),"N/A",IF($U11="Profit",$Q11/$H11,IF($U11="Disqualified",-$S11/$H11,0)))))) | U11: =IF(COUNTA($A11:$M11)=0,"",IF(OR(LEFT(LOWER(TRIM($F11&"")),12)="subscription",LOWER(TRIM($F11&""))="membership"),"Subscription",IF(LOWER(TRIM($D11&""))="estimate","Estimate",IF(OR(AND($H11<>"",$H11=0),LEFT(LOWER(TRIM($F11&"")),9)="free game",LOWER(TRIM($F11&""))="free",LOWER(TRIM($F11&""))="free entry"),IF(LOWER($L11&"")="yes","Disqualified — Free Game","Free Game"),IF(LOWER($L11&"")="yes","Disqualified",IF($P11="","",IF(ROUND(IFERROR(VALUE($P11),0)-IFERROR(VALUE($H11),0),2)>0,"Profit","Draw"))))))) | V11: =IF(COUNTA($A11:$M11)=0,"",IF(OR($B11="",$C11="",$U11="Subscription"),"",IFERROR(ROUNDUP(($C11-$B11)/7,0),""))) | W11: =IF(COUNTA($A11:$M11)=0,"",IF(OR($U11="Subscription",$U11=""),"",IF($U11="Estimate","N/A",IF(OR($U11="Free Game",$U11="Disqualified — Free Game"),0,ROUND(IFERROR($Q11,0)-IFERROR($S11,0),2))))) | X11: =IF(COUNTA($A11:$M11)=0,"",IF(OR($U11="Subscription",NOT(ISNUMBER($J11)),NOT(ISNUMBER($I11)),$J11=0,$I11=0,$I11>$J11),"",$J11-$I11)) | Y11: =IF(COUNTA($A11:$M11)=0,"",IF(OR($U11="Subscription",NOT(ISNUMBER($J11)),$J11=0,$X11=""),"",$X11/$J11)) | Z11: =IF(COUNTA($A11:$M11)=0,"",Instructions!$B$29+SUM($W$5:W11))
N12: =IF(COUNTA($A12:$M12)=0,"",IF(OR(LEFT(LOWER(TRIM($F12&"")),12)="subscription",LOWER(TRIM($F12&""))="membership"),"",IF(OR(AND($H12<>"",$H12=0),LEFT(LOWER(TRIM($F12&"")),9)="free game",LOWER(TRIM($F12&""))="free",LOWER(TRIM($F12&""))="free entry"),IF(ISNUMBER($G12),IF(ISNUMBER(SEARCH("non",LOWER($E12&""))),$G12*0.85,$G12),"N/A"),IF($G12="","",IFERROR(IF(ISNUMBER(SEARCH("non",LOWER($E12&""))),$G12*0.85,$G12),""))))) | O12: =IF(COUNTA($A12:$M12)=0,"",IF(OR(LEFT(LOWER(TRIM($F12&"")),12)="subscription",LOWER(TRIM($F12&""))="membership"),"",IF(OR(AND($H12<>"",$H12=0),LEFT(LOWER(TRIM($F12&"")),9)="free game",LOWER(TRIM($F12&""))="free",LOWER(TRIM($F12&""))="free entry"),IF(OR(NOT(ISNUMBER($N12)),NOT(ISNUMBER($I12)),$I12=0),"N/A",IFERROR($N12/$I12,"N/A")),IF(OR($N12="",$I12="",$I12=0),"",IFERROR($N12/$I12,""))))) | P12: =IF(COUNTA($A12:$M12)=0,"",IF(OR(LEFT(LOWER(TRIM($F12&"")),12)="subscription",LOWER(TRIM($F12&""))="membership"),"",IF(LOWER(TRIM($D12&""))="estimate","N/A",IF(LOWER($L12&"")="yes",0,IF(OR(AND($H12<>"",$H12=0),LEFT(LOWER(TRIM($F12&"")),9)="free game",LOWER(TRIM($F12&""))="free",LOWER(TRIM($F12&""))="free entry"),IF(ISNUMBER($K12),$K12,""),IF($K12<>"",$K12,"")))))) | Q12: =IF(COUNTA($A12:$M12)=0,"",IF(OR($U12="Subscription",$U12=""),"",IF($U12="Estimate","N/A",IF($U12="Profit",ROUND(IFERROR($P12,0)-IFERROR($H12,0),2),0)))) | R12: =IF(COUNTA($A12:$M12)=0,"",IF(OR($U12="Subscription",$U12=""),"",IF($U12="Estimate","N/A",IF($U12="Draw",$H12,0)))) | S12: =IF(COUNTA($A12:$M12)=0,"",IF(OR($U12="Subscription",$U12=""),"",IF($U12="Estimate","N/A",IF($U12="Disqualified",$H12,0)))) | T12: =IF(COUNTA($A12:$M12)=0,"",IF(OR($U12="Subscription",$U12=""),"",IF($U12="Estimate","N/A",IF(OR($U12="Free Game",$U12="Disqualified — Free Game",$H12=0),"N/A",IF($U12="Profit",$Q12/$H12,IF($U12="Disqualified",-$S12/$H12,0)))))) | U12: =IF(COUNTA($A12:$M12)=0,"",IF(OR(LEFT(LOWER(TRIM($F12&"")),12)="subscription",LOWER(TRIM($F12&""))="membership"),"Subscription",IF(LOWER(TRIM($D12&""))="estimate","Estimate",IF(OR(AND($H12<>"",$H12=0),LEFT(LOWER(TRIM($F12&"")),9)="free game",LOWER(TRIM($F12&""))="free",LOWER(TRIM($F12&""))="free entry"),IF(LOWER($L12&"")="yes","Disqualified — Free Game","Free Game"),IF(LOWER($L12&"")="yes","Disqualified",IF($P12="","",IF(ROUND(IFERROR(VALUE($P12),0)-IFERROR(VALUE($H12),0),2)>0,"Profit","Draw"))))))) | V12: =IF(COUNTA($A12:$M12)=0,"",IF(OR($B12="",$C12="",$U12="Subscription"),"",IFERROR(ROUNDUP(($C12-$B12)/7,0),""))) | W12: =IF(COUNTA($A12:$M12)=0,"",IF(OR($U12="Subscription",$U12=""),"",IF($U12="Estimate","N/A",IF(OR($U12="Free Game",$U12="Disqualified — Free Game"),0,ROUND(IFERROR($Q12,0)-IFERROR($S12,0),2))))) | X12: =IF(COUNTA($A12:$M12)=0,"",IF(OR($U12="Subscription",NOT(ISNUMBER($J12)),NOT(ISNUMBER($I12)),$J12=0,$I12=0,$I12>$J12),"",$J12-$I12)) | Y12: =IF(COUNTA($A12:$M12)=0,"",IF(OR($U12="Subscription",NOT(ISNUMBER($J12)),$J12=0,$X12=""),"",$X12/$J12)) | Z12: =IF(COUNTA($A12:$M12)=0,"",Instructions!$B$29+SUM($W$5:W12))
N13: =IF(COUNTA($A13:$M13)=0,"",IF(OR(LEFT(LOWER(TRIM($F13&"")),12)="subscription",LOWER(TRIM($F13&""))="membership"),"",IF(OR(AND($H13<>"",$H13=0),LEFT(LOWER(TRIM($F13&"")),9)="free game",LOWER(TRIM($F13&""))="free",LOWER(TRIM($F13&""))="free entry"),IF(ISNUMBER($G13),IF(ISNUMBER(SEARCH("non",LOWER($E13&""))),$G13*0.85,$G13),"N/A"),IF($G13="","",IFERROR(IF(ISNUMBER(SEARCH("non",LOWER($E13&""))),$G13*0.85,$G13),""))))) | O13: =IF(COUNTA($A13:$M13)=0,"",IF(OR(LEFT(LOWER(TRIM($F13&"")),12)="subscription",LOWER(TRIM($F13&""))="membership"),"",IF(OR(AND($H13<>"",$H13=0),LEFT(LOWER(TRIM($F13&"")),9)="free game",LOWER(TRIM($F13&""))="free",LOWER(TRIM($F13&""))="free entry"),IF(OR(NOT(ISNUMBER($N13)),NOT(ISNUMBER($I13)),$I13=0),"N/A",IFERROR($N13/$I13,"N/A")),IF(OR($N13="",$I13="",$I13=0),"",IFERROR($N13/$I13,""))))) | P13: =IF(COUNTA($A13:$M13)=0,"",IF(OR(LEFT(LOWER(TRIM($F13&"")),12)="subscription",LOWER(TRIM($F13&""))="membership"),"",IF(LOWER(TRIM($D13&""))="estimate","N/A",IF(LOWER($L13&"")="yes",0,IF(OR(AND($H13<>"",$H13=0),LEFT(LOWER(TRIM($F13&"")),9)="free game",LOWER(TRIM($F13&""))="free",LOWER(TRIM($F13&""))="free entry"),IF(ISNUMBER($K13),$K13,""),IF($K13<>"",$K13,"")))))) | Q13: =IF(COUNTA($A13:$M13)=0,"",IF(OR($U13="Subscription",$U13=""),"",IF($U13="Estimate","N/A",IF($U13="Profit",ROUND(IFERROR($P13,0)-IFERROR($H13,0),2),0)))) | R13: =IF(COUNTA($A13:$M13)=0,"",IF(OR($U13="Subscription",$U13=""),"",IF($U13="Estimate","N/A",IF($U13="Draw",$H13,0)))) | S13: =IF(COUNTA($A13:$M13)=0,"",IF(OR($U13="Subscription",$U13=""),"",IF($U13="Estimate","N/A",IF($U13="Disqualified",$H13,0)))) | T13: =IF(COUNTA($A13:$M13)=0,"",IF(OR($U13="Subscription",$U13=""),"",IF($U13="Estimate","N/A",IF(OR($U13="Free Game",$U13="Disqualified — Free Game",$H13=0),"N/A",IF($U13="Profit",$Q13/$H13,IF($U13="Disqualified",-$S13/$H13,0)))))) | U13: =IF(COUNTA($A13:$M13)=0,"",IF(OR(LEFT(LOWER(TRIM($F13&"")),12)="subscription",LOWER(TRIM($F13&""))="membership"),"Subscription",IF(LOWER(TRIM($D13&""))="estimate","Estimate",IF(OR(AND($H13<>"",$H13=0),LEFT(LOWER(TRIM($F13&"")),9)="free game",LOWER(TRIM($F13&""))="free",LOWER(TRIM($F13&""))="free entry"),IF(LOWER($L13&"")="yes","Disqualified — Free Game","Free Game"),IF(LOWER($L13&"")="yes","Disqualified",IF($P13="","",IF(ROUND(IFERROR(VALUE($P13),0)-IFERROR(VALUE($H13),0),2)>0,"Profit","Draw"))))))) | V13: =IF(COUNTA($A13:$M13)=0,"",IF(OR($B13="",$C13="",$U13="Subscription"),"",IFERROR(ROUNDUP(($C13-$B13)/7,0),""))) | W13: =IF(COUNTA($A13:$M13)=0,"",IF(OR($U13="Subscription",$U13=""),"",IF($U13="Estimate","N/A",IF(OR($U13="Free Game",$U13="Disqualified — Free Game"),0,ROUND(IFERROR($Q13,0)-IFERROR($S13,0),2))))) | X13: =IF(COUNTA($A13:$M13)=0,"",IF(OR($U13="Subscription",NOT(ISNUMBER($J13)),NOT(ISNUMBER($I13)),$J13=0,$I13=0,$I13>$J13),"",$J13-$I13)) | Y13: =IF(COUNTA($A13:$M13)=0,"",IF(OR($U13="Subscription",NOT(ISNUMBER($J13)),$J13=0,$X13=""),"",$X13/$J13)) | Z13: =IF(COUNTA($A13:$M13)=0,"",Instructions!$B$29+SUM($W$5:W13))
N14: =IF(COUNTA($A14:$M14)=0,"",IF(OR(LEFT(LOWER(TRIM($F14&"")),12)="subscription",LOWER(TRIM($F14&""))="membership"),"",IF(OR(AND($H14<>"",$H14=0),LEFT(LOWER(TRIM($F14&"")),9)="free game",LOWER(TRIM($F14&""))="free",LOWER(TRIM($F14&""))="free entry"),IF(ISNUMBER($G14),IF(ISNUMBER(SEARCH("non",LOWER($E14&""))),$G14*0.85,$G14),"N/A"),IF($G14="","",IFERROR(IF(ISNUMBER(SEARCH("non",LOWER($E14&""))),$G14*0.85,$G14),""))))) | O14: =IF(COUNTA($A14:$M14)=0,"",IF(OR(LEFT(LOWER(TRIM($F14&"")),12)="subscription",LOWER(TRIM($F14&""))="membership"),"",IF(OR(AND($H14<>"",$H14=0),LEFT(LOWER(TRIM($F14&"")),9)="free game",LOWER(TRIM($F14&""))="free",LOWER(TRIM($F14&""))="free entry"),IF(OR(NOT(ISNUMBER($N14)),NOT(ISNUMBER($I14)),$I14=0),"N/A",IFERROR($N14/$I14,"N/A")),IF(OR($N14="",$I14="",$I14=0),"",IFERROR($N14/$I14,""))))) | P14: =IF(COUNTA($A14:$M14)=0,"",IF(OR(LEFT(LOWER(TRIM($F14&"")),12)="subscription",LOWER(TRIM($F14&""))="membership"),"",IF(LOWER(TRIM($D14&""))="estimate","N/A",IF(LOWER($L14&"")="yes",0,IF(OR(AND($H14<>"",$H14=0),LEFT(LOWER(TRIM($F14&"")),9)="free game",LOWER(TRIM($F14&""))="free",LOWER(TRIM($F14&""))="free entry"),IF(ISNUMBER($K14),$K14,""),IF($K14<>"",$K14,"")))))) | Q14: =IF(COUNTA($A14:$M14)=0,"",IF(OR($U14="Subscription",$U14=""),"",IF($U14="Estimate","N/A",IF($U14="Profit",ROUND(IFERROR($P14,0)-IFERROR($H14,0),2),0)))) | R14: =IF(COUNTA($A14:$M14)=0,"",IF(OR($U14="Subscription",$U14=""),"",IF($U14="Estimate","N/A",IF($U14="Draw",$H14,0)))) | S14: =IF(COUNTA($A14:$M14)=0,"",IF(OR($U14="Subscription",$U14=""),"",IF($U14="Estimate","N/A",IF($U14="Disqualified",$H14,0)))) | T14: =IF(COUNTA($A14:$M14)=0,"",IF(OR($U14="Subscription",$U14=""),"",IF($U14="Estimate","N/A",IF(OR($U14="Free Game",$U14="Disqualified — Free Game",$H14=0),"N/A",IF($U14="Profit",$Q14/$H14,IF($U14="Disqualified",-$S14/$H14,0)))))) | U14: =IF(COUNTA($A14:$M14)=0,"",IF(OR(LEFT(LOWER(TRIM($F14&"")),12)="subscription",LOWER(TRIM($F14&""))="membership"),"Subscription",IF(LOWER(TRIM($D14&""))="estimate","Estimate",IF(OR(AND($H14<>"",$H14=0),LEFT(LOWER(TRIM($F14&"")),9)="free game",LOWER(TRIM($F14&""))="free",LOWER(TRIM($F14&""))="free entry"),IF(LOWER($L14&"")="yes","Disqualified — Free Game","Free Game"),IF(LOWER($L14&"")="yes","Disqualified",IF($P14="","",IF(ROUND(IFERROR(VALUE($P14),0)-IFERROR(VALUE($H14),0),2)>0,"Profit","Draw"))))))) | V14: =IF(COUNTA($A14:$M14)=0,"",IF(OR($B14="",$C14="",$U14="Subscription"),"",IFERROR(ROUNDUP(($C14-$B14)/7,0),""))) | W14: =IF(COUNTA($A14:$M14)=0,"",IF(OR($U14="Subscription",$U14=""),"",IF($U14="Estimate","N/A",IF(OR($U14="Free Game",$U14="Disqualified — Free Game"),0,ROUND(IFERROR($Q14,0)-IFERROR($S14,0),2))))) | X14: =IF(COUNTA($A14:$M14)=0,"",IF(OR($U14="Subscription",NOT(ISNUMBER($J14)),NOT(ISNUMBER($I14)),$J14=0,$I14=0,$I14>$J14),"",$J14-$I14)) | Y14: =IF(COUNTA($A14:$M14)=0,"",IF(OR($U14="Subscription",NOT(ISNUMBER($J14)),$J14=0,$X14=""),"",$X14/$J14)) | Z14: =IF(COUNTA($A14:$M14)=0,"",Instructions!$B$29+SUM($W$5:W14))
N15: =IF(COUNTA($A15:$M15)=0,"",IF(OR(LEFT(LOWER(TRIM($F15&"")),12)="subscription",LOWER(TRIM($F15&""))="membership"),"",IF(OR(AND($H15<>"",$H15=0),LEFT(LOWER(TRIM($F15&"")),9)="free game",LOWER(TRIM($F15&""))="free",LOWER(TRIM($F15&""))="free entry"),IF(ISNUMBER($G15),IF(ISNUMBER(SEARCH("non",LOWER($E15&""))),$G15*0.85,$G15),"N/A"),IF($G15="","",IFERROR(IF(ISNUMBER(SEARCH("non",LOWER($E15&""))),$G15*0.85,$G15),""))))) | O15: =IF(COUNTA($A15:$M15)=0,"",IF(OR(LEFT(LOWER(TRIM($F15&"")),12)="subscription",LOWER(TRIM($F15&""))="membership"),"",IF(OR(AND($H15<>"",$H15=0),LEFT(LOWER(TRIM($F15&"")),9)="free game",LOWER(TRIM($F15&""))="free",LOWER(TRIM($F15&""))="free entry"),IF(OR(NOT(ISNUMBER($N15)),NOT(ISNUMBER($I15)),$I15=0),"N/A",IFERROR($N15/$I15,"N/A")),IF(OR($N15="",$I15="",$I15=0),"",IFERROR($N15/$I15,""))))) | P15: =IF(COUNTA($A15:$M15)=0,"",IF(OR(LEFT(LOWER(TRIM($F15&"")),12)="subscription",LOWER(TRIM($F15&""))="membership"),"",IF(LOWER(TRIM($D15&""))="estimate","N/A",IF(LOWER($L15&"")="yes",0,IF(OR(AND($H15<>"",$H15=0),LEFT(LOWER(TRIM($F15&"")),9)="free game",LOWER(TRIM($F15&""))="free",LOWER(TRIM($F15&""))="free entry"),IF(ISNUMBER($K15),$K15,""),IF($K15<>"",$K15,"")))))) | Q15: =IF(COUNTA($A15:$M15)=0,"",IF(OR($U15="Subscription",$U15=""),"",IF($U15="Estimate","N/A",IF($U15="Profit",ROUND(IFERROR($P15,0)-IFERROR($H15,0),2),0)))) | R15: =IF(COUNTA($A15:$M15)=0,"",IF(OR($U15="Subscription",$U15=""),"",IF($U15="Estimate","N/A",IF($U15="Draw",$H15,0)))) | S15: =IF(COUNTA($A15:$M15)=0,"",IF(OR($U15="Subscription",$U15=""),"",IF($U15="Estimate","N/A",IF($U15="Disqualified",$H15,0)))) | T15: =IF(COUNTA($A15:$M15)=0,"",IF(OR($U15="Subscription",$U15=""),"",IF($U15="Estimate","N/A",IF(OR($U15="Free Game",$U15="Disqualified — Free Game",$H15=0),"N/A",IF($U15="Profit",$Q15/$H15,IF($U15="Disqualified",-$S15/$H15,0)))))) | U15: =IF(COUNTA($A15:$M15)=0,"",IF(OR(LEFT(LOWER(TRIM($F15&"")),12)="subscription",LOWER(TRIM($F15&""))="membership"),"Subscription",IF(LOWER(TRIM($D15&""))="estimate","Estimate",IF(OR(AND($H15<>"",$H15=0),LEFT(LOWER(TRIM($F15&"")),9)="free game",LOWER(TRIM($F15&""))="free",LOWER(TRIM($F15&""))="free entry"),IF(LOWER($L15&"")="yes","Disqualified — Free Game","Free Game"),IF(LOWER($L15&"")="yes","Disqualified",IF($P15="","",IF(ROUND(IFERROR(VALUE($P15),0)-IFERROR(VALUE($H15),0),2)>0,"Profit","Draw"))))))) | V15: =IF(COUNTA($A15:$M15)=0,"",IF(OR($B15="",$C15="",$U15="Subscription"),"",IFERROR(ROUNDUP(($C15-$B15)/7,0),""))) | W15: =IF(COUNTA($A15:$M15)=0,"",IF(OR($U15="Subscription",$U15=""),"",IF($U15="Estimate","N/A",IF(OR($U15="Free Game",$U15="Disqualified — Free Game"),0,ROUND(IFERROR($Q15,0)-IFERROR($S15,0),2))))) | X15: =IF(COUNTA($A15:$M15)=0,"",IF(OR($U15="Subscription",NOT(ISNUMBER($J15)),NOT(ISNUMBER($I15)),$J15=0,$I15=0,$I15>$J15),"",$J15-$I15)) | Y15: =IF(COUNTA($A15:$M15)=0,"",IF(OR($U15="Subscription",NOT(ISNUMBER($J15)),$J15=0,$X15=""),"",$X15/$J15)) | Z15: =IF(COUNTA($A15:$M15)=0,"",Instructions!$B$29+SUM($W$5:W15))
N16: =IF(COUNTA($A16:$M16)=0,"",IF(OR(LEFT(LOWER(TRIM($F16&"")),12)="subscription",LOWER(TRIM($F16&""))="membership"),"",IF(OR(AND($H16<>"",$H16=0),LEFT(LOWER(TRIM($F16&"")),9)="free game",LOWER(TRIM($F16&""))="free",LOWER(TRIM($F16&""))="free entry"),IF(ISNUMBER($G16),IF(ISNUMBER(SEARCH("non",LOWER($E16&""))),$G16*0.85,$G16),"N/A"),IF($G16="","",IFERROR(IF(ISNUMBER(SEARCH("non",LOWER($E16&""))),$G16*0.85,$G16),""))))) | O16: =IF(COUNTA($A16:$M16)=0,"",IF(OR(LEFT(LOWER(TRIM($F16&"")),12)="subscription",LOWER(TRIM($F16&""))="membership"),"",IF(OR(AND($H16<>"",$H16=0),LEFT(LOWER(TRIM($F16&"")),9)="free game",LOWER(TRIM($F16&""))="free",LOWER(TRIM($F16&""))="free entry"),IF(OR(NOT(ISNUMBER($N16)),NOT(ISNUMBER($I16)),$I16=0),"N/A",IFERROR($N16/$I16,"N/A")),IF(OR($N16="",$I16="",$I16=0),"",IFERROR($N16/$I16,""))))) | P16: =IF(COUNTA($A16:$M16)=0,"",IF(OR(LEFT(LOWER(TRIM($F16&"")),12)="subscription",LOWER(TRIM($F16&""))="membership"),"",IF(LOWER(TRIM($D16&""))="estimate","N/A",IF(LOWER($L16&"")="yes",0,IF(OR(AND($H16<>"",$H16=0),LEFT(LOWER(TRIM($F16&"")),9)="free game",LOWER(TRIM($F16&""))="free",LOWER(TRIM($F16&""))="free entry"),IF(ISNUMBER($K16),$K16,""),IF($K16<>"",$K16,"")))))) | Q16: =IF(COUNTA($A16:$M16)=0,"",IF(OR($U16="Subscription",$U16=""),"",IF($U16="Estimate","N/A",IF($U16="Profit",ROUND(IFERROR($P16,0)-IFERROR($H16,0),2),0)))) | R16: =IF(COUNTA($A16:$M16)=0,"",IF(OR($U16="Subscription",$U16=""),"",IF($U16="Estimate","N/A",IF($U16="Draw",$H16,0)))) | S16: =IF(COUNTA($A16:$M16)=0,"",IF(OR($U16="Subscription",$U16=""),"",IF($U16="Estimate","N/A",IF($U16="Disqualified",$H16,0)))) | T16: =IF(COUNTA($A16:$M16)=0,"",IF(OR($U16="Subscription",$U16=""),"",IF($U16="Estimate","N/A",IF(OR($U16="Free Game",$U16="Disqualified — Free Game",$H16=0),"N/A",IF($U16="Profit",$Q16/$H16,IF($U16="Disqualified",-$S16/$H16,0)))))) | U16: =IF(COUNTA($A16:$M16)=0,"",IF(OR(LEFT(LOWER(TRIM($F16&"")),12)="subscription",LOWER(TRIM($F16&""))="membership"),"Subscription",IF(LOWER(TRIM($D16&""))="estimate","Estimate",IF(OR(AND($H16<>"",$H16=0),LEFT(LOWER(TRIM($F16&"")),9)="free game",LOWER(TRIM($F16&""))="free",LOWER(TRIM($F16&""))="free entry"),IF(LOWER($L16&"")="yes","Disqualified — Free Game","Free Game"),IF(LOWER($L16&"")="yes","Disqualified",IF($P16="","",IF(ROUND(IFERROR(VALUE($P16),0)-IFERROR(VALUE($H16),0),2)>0,"Profit","Draw"))))))) | V16: =IF(COUNTA($A16:$M16)=0,"",IF(OR($B16="",$C16="",$U16="Subscription"),"",IFERROR(ROUNDUP(($C16-$B16)/7,0),""))) | W16: =IF(COUNTA($A16:$M16)=0,"",IF(OR($U16="Subscription",$U16=""),"",IF($U16="Estimate","N/A",IF(OR($U16="Free Game",$U16="Disqualified — Free Game"),0,ROUND(IFERROR($Q16,0)-IFERROR($S16,0),2))))) | X16: =IF(COUNTA($A16:$M16)=0,"",IF(OR($U16="Subscription",NOT(ISNUMBER($J16)),NOT(ISNUMBER($I16)),$J16=0,$I16=0,$I16>$J16),"",$J16-$I16)) | Y16: =IF(COUNTA($A16:$M16)=0,"",IF(OR($U16="Subscription",NOT(ISNUMBER($J16)),$J16=0,$X16=""),"",$X16/$J16)) | Z16: =IF(COUNTA($A16:$M16)=0,"",Instructions!$B$29+SUM($W$5:W16))
... N504: =IF(COUNTA($A504:$M504)=0,"",IF(OR(LEFT(LOWER(TRIM($F504&"")),12)="subscription",LOWER(TRIM($F504&""))="membership"),"",IF(OR(AND($H504<>"",$H504=0),LEFT(LOWER(TRIM($F504&"")),9)="free game",LOWER(TRIM($F504&""))="free",LOWER(TRIM($F504&""))="free entry"),IF(ISNUMBER($G504),IF(ISNUMBER(SEARCH("non",LOWER($E504&""))),$G504*0.85,$G504),"N/A"),IF($G504="","",IFERROR(IF(ISNUMBER(SEARCH("non",LOWER($E504&""))),$G504*0.85,$G504),""))))) | O504: =IF(COUNTA($A504:$M504)=0,"",IF(OR(LEFT(LOWER(TRIM($F504&"")),12)="subscription",LOWER(TRIM($F504&""))="membership"),"",IF(OR(AND($H504<>"",$H504=0),LEFT(LOWER(TRIM($F504&"")),9)="free game",LOWER(TRIM($F504&""))="free",LOWER(TRIM($F504&""))="free entry"),IF(OR(NOT(ISNUMBER($N504)),NOT(ISNUMBER($I504)),$I504=0),"N/A",IFERROR($N504/$I504,"N/A")),IF(OR($N504="",$I504="",$I504=0),"",IFERROR($N504/$I504,""))))) | P504: =IF(COUNTA($A504:$M504)=0,"",IF(OR(LEFT(LOWER(TRIM($F504&"")),12)="subscription",LOWER(TRIM($F504&""))="membership"),"",IF(LOWER(TRIM($D504&""))="estimate","N/A",IF(LOWER($L504&"")="yes",0,IF(OR(AND($H504<>"",$H504=0),LEFT(LOWER(TRIM($F504&"")),9)="free game",LOWER(TRIM($F504&""))="free",LOWER(TRIM($F504&""))="free entry"),IF(ISNUMBER($K504),$K504,""),IF($K504<>"",$K504,"")))))) | Q504: =IF(COUNTA($A504:$M504)=0,"",IF(OR($U504="Subscription",$U504=""),"",IF($U504="Estimate","N/A",IF($U504="Profit",ROUND(IFERROR($P504,0)-IFERROR($H504,0),2),0)))) | R504: =IF(COUNTA($A504:$M504)=0,"",IF(OR($U504="Subscription",$U504=""),"",IF($U504="Estimate","N/A",IF($U504="Draw",$H504,0)))) | S504: =IF(COUNTA($A504:$M504)=0,"",IF(OR($U504="Subscription",$U504=""),"",IF($U504="Estimate","N/A",IF($U504="Disqualified",$H504,0)))) | T504: =IF(COUNTA($A504:$M504)=0,"",IF(OR($U504="Subscription",$U504=""),"",IF($U504="Estimate","N/A",IF(OR($U504="Free Game",$U504="Disqualified — Free Game",$H504=0),"N/A",IF($U504="Profit",$Q504/$H504,IF($U504="Disqualified",-$S504/$H504,0)))))) | U504: =IF(COUNTA($A504:$M504)=0,"",IF(OR(LEFT(LOWER(TRIM($F504&"")),12)="subscription",LOWER(TRIM($F504&""))="membership"),"Subscription",IF(LOWER(TRIM($D504&""))="estimate","Estimate",IF(OR(AND($H504<>"",$H504=0),LEFT(LOWER(TRIM($F504&"")),9)="free game",LOWER(TRIM($F504&""))="free",LOWER(TRIM($F504&""))="free entry"),IF(LOWER($L504&"")="yes","Disqualified — Free Game","Free Game"),IF(LOWER($L504&"")="yes","Disqualified",IF($P504="","",IF(ROUND(IFERROR(VALUE($P504),0)-IFERROR(VALUE($H504),0),2)>0,"Profit","Draw"))))))) | V504: =IF(COUNTA($A504:$M504)=0,"",IF(OR($B504="",$C504="",$U504="Subscription"),"",IFERROR(ROUNDUP(($C504-$B504)/7,0),""))) | W504: =IF(COUNTA($A504:$M504)=0,"",IF(OR($U504="Subscription",$U504=""),"",IF($U504="Estimate","N/A",IF(OR($U504="Free Game",$U504="Disqualified — Free Game"),0,ROUND(IFERROR($Q504,0)-IFERROR($S504,0),2))))) | X504: =IF(COUNTA($A504:$M504)=0,"",IF(OR($U504="Subscription",NOT(ISNUMBER($J504)),NOT(ISNUMBER($I504)),$J504=0,$I504=0,$I504>$J504),"",$J504-$I504)) | Y504: =IF(COUNTA($A504:$M504)=0,"",IF(OR($U504="Subscription",NOT(ISNUMBER($J504)),$J504=0,$X504=""),"",$X504/$J504)) | Z504: =IF(COUNTA($A504:$M504)=0,"",Instructions!$B$29+SUM($W$5:W504))
A505: END OF WORKBOOK — 500 RECORD ROWS USED. ARCHIVE THIS FILE AND BEGIN A FRESH COPY. DO NOT ENTER RECORDS BELOW THIS ROW.

Sheet Record Review
A1: Record Review — Game Index and Field Review — v252
A2: Formula-driven view only — do not type or paste into Record Review. Enter or edit records in Game Records A–M. Blank rows are expected until matching non-subscription games exist. Selecting a prepared cell may show a formula in the formula bar; the worksheet cell should display its calculated result or remain blank.
A4: Game # | B4: Game Records ID | C4: Game Name | D4: Calculated Result | E4: Review Status | F4: What to Review | G4: Notes from Game Records
A5: =IF($H5="","",ROWS($A$5:A5)) | B5: =IF($H5="","","G-"&TEXT($A5,"0000")) | C5: =IF($H5="","",IFERROR(INDEX('Game Records'!$A:$A,$H5),"")) | D5: =IF($H5="","",IFERROR(INDEX('Game Records'!$U:$U,$H5),"")) | E5: =IF($H5="","",IF($F5="","No Highlighted Fields","Highlighted Fields Present")) | F5: =IF($H5="","",IF(OR(NOT(ISFORMULA(INDEX('Game Records'!$N:$N,$H5))),NOT(ISFORMULA(INDEX('Game Records'!$O:$O,$H5))),NOT(ISFORMULA(INDEX('Game Records'!$P:$P,$H5))),NOT(ISFORMULA(INDEX('Game Records'!$Q:$Q,$H5))),NOT(ISFORMULA(INDEX('Game Records'!$R:$R,$H5))),NOT(ISFORMULA(INDEX('Game Records'!$S:$S,$H5))),NOT(ISFORMULA(INDEX('Game Records'!$T:$T,$H5))),NOT(ISFORMULA(INDEX('Game Records'!$U:$U,$H5))),NOT(ISFORMULA(INDEX('Game Records'!$V:$V,$H5))),NOT(ISFORMULA(INDEX('Game Records'!$W:$W,$H5))),NOT(ISFORMULA(INDEX('Game Records'!$X:$X,$H5))),NOT(ISFORMULA(INDEX('Game Records'!$Y:$Y,$H5))),NOT(ISFORMULA(INDEX('Game Records'!$Z:$Z,$H5)))),"Formula columns missing; ","")&IF(INDEX('Game Records'!$B:$B,$H5)="","Start Date; ","")&IF(INDEX('Game Records'!$C:$C,$H5)="","End Date; ","")&IF(AND(INDEX('Game Records'!$U:$U,$H5)<>"Subscription",INDEX('Game Records'!$U:$U,$H5)<>"Free Game",INDEX('Game Records'!$U:$U,$H5)<>"Disqualified — Free Game",OR(INDEX('Game Records'!$D:$D,$H5)="",LOWER(INDEX('Game Records'!$D:$D,$H5)&"")="n/a")),"Entry Mode; ","")&IF(AND(INDEX('Game Records'!$U:$U,$H5)<>"Subscription",INDEX('Game Records'!$U:$U,$H5)<>"Free Game",INDEX('Game Records'!$U:$U,$H5)<>"Disqualified — Free Game",OR(INDEX('Game Records'!$E:$E,$H5)="",LOWER(INDEX('Game Records'!$E:$E,$H5)&"")="n/a")),"Game Type; ","")&IF(INDEX('Game Records'!$F:$F,$H5)="","Payment Type; ","")&IF(AND(INDEX('Game Records'!$U:$U,$H5)<>"Subscription",INDEX('Game Records'!$U:$U,$H5)<>"Free Game",INDEX('Game Records'!$U:$U,$H5)<>"Disqualified — Free Game",INDEX('Game Records'!$G:$G,$H5)=""),"Gross Pot; ","")&IF(AND(INDEX('Game Records'!$U:$U,$H5)<>"Free Game",INDEX('Game Records'!$U:$U,$H5)<>"Disqualified — Free Game",INDEX('Game Records'!$H:$H,$H5)=""),"Entry Fee; ","")&IF(AND(INDEX('Game Records'!$U:$U,$H5)<>"Subscription",INDEX('Game Records'!$U:$U,$H5)<>"Free Game",INDEX('Game Records'!$U:$U,$H5)<>"Disqualified — Free Game",INDEX('Game Records'!$I:$I,$H5)=""),"Eligible Players; ","")&IF(AND(INDEX('Game Records'!$U:$U,$H5)<>"Subscription",INDEX('Game Records'!$U:$U,$H5)<>"Free Game",INDEX('Game Records'!$U:$U,$H5)<>"Disqualified — Free Game",INDEX('Game Records'!$J:$J,$H5)=""),"Total Players; ","")&IF(AND(LOWER(INDEX('Game Records'!$D:$D,$H5)&"")="finalized",LOWER(INDEX('Game Records'!$L:$L,$H5)&"")<>"yes",INDEX('Game Records'!$U:$U,$H5)<>"Subscription",INDEX('Game Records'!$U:$U,$H5)<>"Free Game",INDEX('Game Records'!$U:$U,$H5)<>"Disqualified — Free Game",INDEX('Game Records'!$K:$K,$H5)=""),"Final Earned; ","")&IF(AND(LOWER(INDEX('Game Records'!$D:$D,$H5)&"")="finalized",INDEX('Game Records'!$U:$U,$H5)<>"Subscription",INDEX('Game Records'!$U:$U,$H5)<>"Free Game",INDEX('Game Records'!$U:$U,$H5)<>"Disqualified — Free Game",OR(INDEX('Game Records'!$L:$L,$H5)="",LOWER(INDEX('Game Records'!$L:$L,$H5)&"")="n/a")),"Disqualified Status; ","")&IF(AND(OR(LOWER(TRIM(INDEX('Game Records'!$F:$F,$H5)&""))="free game",INDEX('Game Records'!$U:$U,$H5)="Free Game",INDEX('Game Records'!$U:$U,$H5)="Disqualified — Free Game"),N(INDEX('Game Records'!$H:$H,$H5))<>0),"Free Game has a non-zero Entry Fee. Free Game records require a $0 Entry Fee; ","")) | G5: =IF($H5="","",IFERROR(INDEX('Game Records'!$M:$M,$H5),"")) | H5: =IFERROR(MATCH(1,INDEX((('Game Records'!$A$5:$A$504<>"")+('Game Records'!$B$5:$B$504<>"")+('Game Records'!$C$5:$C$504<>"")+('Game Records'!$D$5:$D$504<>"")+('Game Records'!$E$5:$E$504<>"")+('Game Records'!$F$5:$F$504<>"")+('Game Records'!$G$5:$G$504<>"")+('Game Records'!$H$5:$H$504<>"")+('Game Records'!$I$5:$I$504<>"")+('Game Records'!$J$5:$J$504<>"")+('Game Records'!$K$5:$K$504<>"")+('Game Records'!$L$5:$L$504<>"")+('Game Records'!$M$5:$M$504<>"")>0)*('Game Records'!$U$5:$U$504<>"Subscription"),0),0)+4,"") | I5: Review Totals
A6: =IF($H6="","",ROWS($A$5:A6)) | B6: =IF($H6="","","G-"&TEXT($A6,"0000")) | C6: =IF($H6="","",IFERROR(INDEX('Game Records'!$A:$A,$H6),"")) | D6: =IF($H6="","",IFERROR(INDEX('Game Records'!$U:$U,$H6),"")) | E6: =IF($H6="","",IF($F6="","No Highlighted Fields","Highlighted Fields Present")) | F6: =IF($H6="","",IF(OR(NOT(ISFORMULA(INDEX('Game Records'!$N:$N,$H6))),NOT(ISFORMULA(INDEX('Game Records'!$O:$O,$H6))),NOT(ISFORMULA(INDEX('Game Records'!$P:$P,$H6))),NOT(ISFORMULA(INDEX('Game Records'!$Q:$Q,$H6))),NOT(ISFORMULA(INDEX('Game Records'!$R:$R,$H6))),NOT(ISFORMULA(INDEX('Game Records'!$S:$S,$H6))),NOT(ISFORMULA(INDEX('Game Records'!$T:$T,$H6))),NOT(ISFORMULA(INDEX('Game Records'!$U:$U,$H6))),NOT(ISFORMULA(INDEX('Game Records'!$V:$V,$H6))),NOT(ISFORMULA(INDEX('Game Records'!$W:$W,$H6))),NOT(ISFORMULA(INDEX('Game Records'!$X:$X,$H6))),NOT(ISFORMULA(INDEX('Game Records'!$Y:$Y,$H6))),NOT(ISFORMULA(INDEX('Game Records'!$Z:$Z,$H6)))),"Formula columns missing; ","")&IF(INDEX('Game Records'!$B:$B,$H6)="","Start Date; ","")&IF(INDEX('Game Records'!$C:$C,$H6)="","End Date; ","")&IF(AND(INDEX('Game Records'!$U:$U,$H6)<>"Subscription",INDEX('Game Records'!$U:$U,$H6)<>"Free Game",INDEX('Game Records'!$U:$U,$H6)<>"Disqualified — Free Game",OR(INDEX('Game Records'!$D:$D,$H6)="",LOWER(INDEX('Game Records'!$D:$D,$H6)&"")="n/a")),"Entry Mode; ","")&IF(AND(INDEX('Game Records'!$U:$U,$H6)<>"Subscription",INDEX('Game Records'!$U:$U,$H6)<>"Free Game",INDEX('Game Records'!$U:$U,$H6)<>"Disqualified — Free Game",OR(INDEX('Game Records'!$E:$E,$H6)="",LOWER(INDEX('Game Records'!$E:$E,$H6)&"")="n/a")),"Game Type; ","")&IF(INDEX('Game Records'!$F:$F,$H6)="","Payment Type; ","")&IF(AND(INDEX('Game Records'!$U:$U,$H6)<>"Subscription",INDEX('Game Records'!$U:$U,$H6)<>"Free Game",INDEX('Game Records'!$U:$U,$H6)<>"Disqualified — Free Game",INDEX('Game Records'!$G:$G,$H6)=""),"Gross Pot; ","")&IF(AND(INDEX('Game Records'!$U:$U,$H6)<>"Free Game",INDEX('Game Records'!$U:$U,$H6)<>"Disqualified — Free Game",INDEX('Game Records'!$H:$H,$H6)=""),"Entry Fee; ","")&IF(AND(INDEX('Game Records'!$U:$U,$H6)<>"Subscription",INDEX('Game Records'!$U:$U,$H6)<>"Free Game",INDEX('Game Records'!$U:$U,$H6)<>"Disqualified — Free Game",INDEX('Game Records'!$I:$I,$H6)=""),"Eligible Players; ","")&IF(AND(INDEX('Game Records'!$U:$U,$H6)<>"Subscription",INDEX('Game Records'!$U:$U,$H6)<>"Free Game",INDEX('Game Records'!$U:$U,$H6)<>"Disqualified — Free Game",INDEX('Game Records'!$J:$J,$H6)=""),"Total Players; ","")&IF(AND(LOWER(INDEX('Game Records'!$D:$D,$H6)&"")="finalized",LOWER(INDEX('Game Records'!$L:$L,$H6)&"")<>"yes",INDEX('Game Records'!$U:$U,$H6)<>"Subscription",INDEX('Game Records'!$U:$U,$H6)<>"Free Game",INDEX('Game Records'!$U:$U,$H6)<>"Disqualified — Free Game",INDEX('Game Records'!$K:$K,$H6)=""),"Final Earned; ","")&IF(AND(LOWER(INDEX('Game Records'!$D:$D,$H6)&"")="finalized",INDEX('Game Records'!$U:$U,$H6)<>"Subscription",INDEX('Game Records'!$U:$U,$H6)<>"Free Game",INDEX('Game Records'!$U:$U,$H6)<>"Disqualified — Free Game",OR(INDEX('Game Records'!$L:$L,$H6)="",LOWER(INDEX('Game Records'!$L:$L,$H6)&"")="n/a")),"Disqualified Status; ","")&IF(AND(OR(LOWER(TRIM(INDEX('Game Records'!$F:$F,$H6)&""))="free game",INDEX('Game Records'!$U:$U,$H6)="Free Game",INDEX('Game Records'!$U:$U,$H6)="Disqualified — Free Game"),N(INDEX('Game Records'!$H:$H,$H6))<>0),"Free Game has a non-zero Entry Fee. Free Game records require a $0 Entry Fee; ","")) | G6: =IF($H6="","",IFERROR(INDEX('Game Records'!$M:$M,$H6),"")) | H6: =IF($H5="","",IFERROR(MATCH(1,INDEX((ROW('Game Records'!$U$5:$U$504)>$H5)*(('Game Records'!$A$5:$A$504<>"")+('Game Records'!$B$5:$B$504<>"")+('Game Records'!$C$5:$C$504<>"")+('Game Records'!$D$5:$D$504<>"")+('Game Records'!$E$5:$E$504<>"")+('Game Records'!$F$5:$F$504<>"")+('Game Records'!$G$5:$G$504<>"")+('Game Records'!$H$5:$H$504<>"")+('Game Records'!$I$5:$I$504<>"")+('Game Records'!$J$5:$J$504<>"")+('Game Records'!$K$5:$K$504<>"")+('Game Records'!$L$5:$L$504<>"")+('Game Records'!$M$5:$M$504<>"")>0)*('Game Records'!$U$5:$U$504<>"Subscription"),0),0)+4,"")) | I6: Total Games | J6: =COUNT($A$5:$A$504) -> 0
A7: =IF($H7="","",ROWS($A$5:A7)) | B7: =IF($H7="","","G-"&TEXT($A7,"0000")) | C7: =IF($H7="","",IFERROR(INDEX('Game Records'!$A:$A,$H7),"")) | D7: =IF($H7="","",IFERROR(INDEX('Game Records'!$U:$U,$H7),"")) | E7: =IF($H7="","",IF($F7="","No Highlighted Fields","Highlighted Fields Present")) | F7: =IF($H7="","",IF(OR(NOT(ISFORMULA(INDEX('Game Records'!$N:$N,$H7))),NOT(ISFORMULA(INDEX('Game Records'!$O:$O,$H7))),NOT(ISFORMULA(INDEX('Game Records'!$P:$P,$H7))),NOT(ISFORMULA(INDEX('Game Records'!$Q:$Q,$H7))),NOT(ISFORMULA(INDEX('Game Records'!$R:$R,$H7))),NOT(ISFORMULA(INDEX('Game Records'!$S:$S,$H7))),NOT(ISFORMULA(INDEX('Game Records'!$T:$T,$H7))),NOT(ISFORMULA(INDEX('Game Records'!$U:$U,$H7))),NOT(ISFORMULA(INDEX('Game Records'!$V:$V,$H7))),NOT(ISFORMULA(INDEX('Game Records'!$W:$W,$H7))),NOT(ISFORMULA(INDEX('Game Records'!$X:$X,$H7))),NOT(ISFORMULA(INDEX('Game Records'!$Y:$Y,$H7))),NOT(ISFORMULA(INDEX('Game Records'!$Z:$Z,$H7)))),"Formula columns missing; ","")&IF(INDEX('Game Records'!$B:$B,$H7)="","Start Date; ","")&IF(INDEX('Game Records'!$C:$C,$H7)="","End Date; ","")&IF(AND(INDEX('Game Records'!$U:$U,$H7)<>"Subscription",INDEX('Game Records'!$U:$U,$H7)<>"Free Game",INDEX('Game Records'!$U:$U,$H7)<>"Disqualified — Free Game",OR(INDEX('Game Records'!$D:$D,$H7)="",LOWER(INDEX('Game Records'!$D:$D,$H7)&"")="n/a")),"Entry Mode; ","")&IF(AND(INDEX('Game Records'!$U:$U,$H7)<>"Subscription",INDEX('Game Records'!$U:$U,$H7)<>"Free Game",INDEX('Game Records'!$U:$U,$H7)<>"Disqualified — Free Game",OR(INDEX('Game Records'!$E:$E,$H7)="",LOWER(INDEX('Game Records'!$E:$E,$H7)&"")="n/a")),"Game Type; ","")&IF(INDEX('Game Records'!$F:$F,$H7)="","Payment Type; ","")&IF(AND(INDEX('Game Records'!$U:$U,$H7)<>"Subscription",INDEX('Game Records'!$U:$U,$H7)<>"Free Game",INDEX('Game Records'!$U:$U,$H7)<>"Disqualified — Free Game",INDEX('Game Records'!$G:$G,$H7)=""),"Gross Pot; ","")&IF(AND(INDEX('Game Records'!$U:$U,$H7)<>"Free Game",INDEX('Game Records'!$U:$U,$H7)<>"Disqualified — Free Game",INDEX('Game Records'!$H:$H,$H7)=""),"Entry Fee; ","")&IF(AND(INDEX('Game Records'!$U:$U,$H7)<>"Subscription",INDEX('Game Records'!$U:$U,$H7)<>"Free Game",INDEX('Game Records'!$U:$U,$H7)<>"Disqualified — Free Game",INDEX('Game Records'!$I:$I,$H7)=""),"Eligible Players; ","")&IF(AND(INDEX('Game Records'!$U:$U,$H7)<>"Subscription",INDEX('Game Records'!$U:$U,$H7)<>"Free Game",INDEX('Game Records'!$U:$U,$H7)<>"Disqualified — Free Game",INDEX('Game Records'!$J:$J,$H7)=""),"Total Players; ","")&IF(AND(LOWER(INDEX('Game Records'!$D:$D,$H7)&"")="finalized",LOWER(INDEX('Game Records'!$L:$L,$H7)&"")<>"yes",INDEX('Game Records'!$U:$U,$H7)<>"Subscription",INDEX('Game Records'!$U:$U,$H7)<>"Free Game",INDEX('Game Records'!$U:$U,$H7)<>"Disqualified — Free Game",INDEX('Game Records'!$K:$K,$H7)=""),"Final Earned; ","")&IF(AND(LOWER(INDEX('Game Records'!$D:$D,$H7)&"")="finalized",INDEX('Game Records'!$U:$U,$H7)<>"Subscription",INDEX('Game Records'!$U:$U,$H7)<>"Free Game",INDEX('Game Records'!$U:$U,$H7)<>"Disqualified — Free Game",OR(INDEX('Game Records'!$L:$L,$H7)="",LOWER(INDEX('Game Records'!$L:$L,$H7)&"")="n/a")),"Disqualified Status; ","")&IF(AND(OR(LOWER(TRIM(INDEX('Game Records'!$F:$F,$H7)&""))="free game",INDEX('Game Records'!$U:$U,$H7)="Free Game",INDEX('Game Records'!$U:$U,$H7)="Disqualified — Free Game"),N(INDEX('Game Records'!$H:$H,$H7))<>0),"Free Game has a non-zero Entry Fee. Free Game records require a $0 Entry Fee; ","")) | G7: =IF($H7="","",IFERROR(INDEX('Game Records'!$M:$M,$H7),"")) | H7: =IF($H6="","",IFERROR(MATCH(1,INDEX((ROW('Game Records'!$U$5:$U$504)>$H6)*(('Game Records'!$A$5:$A$504<>"")+('Game Records'!$B$5:$B$504<>"")+('Game Records'!$C$5:$C$504<>"")+('Game Records'!$D$5:$D$504<>"")+('Game Records'!$E$5:$E$504<>"")+('Game Records'!$F$5:$F$504<>"")+('Game Records'!$G$5:$G$504<>"")+('Game Records'!$H$5:$H$504<>"")+('Game Records'!$I$5:$I$504<>"")+('Game Records'!$J$5:$J$504<>"")+('Game Records'!$K$5:$K$504<>"")+('Game Records'!$L$5:$L$504<>"")+('Game Records'!$M$5:$M$504<>"")>0)*('Game Records'!$U$5:$U$504<>"Subscription"),0),0)+4,"")) | I7: Profit Games | J7: =COUNTIF('Game Records'!$U$5:$U$504,"Profit") -> 0
